Workbook

Sheet 202202KSRheinbergerMühlen
A1: Projektname | B1: =IF(Projektinfo!B1="","",Projektinfo!B1) -> 2022-02_KS_Rheinberger/Mühlen
A2: MwSt.
A3: Typ | B3: Ordnungszahl | C3: Kurztext | D3: Langtext | E3: Menge | F3: Einheit | G3: Einheitspreis | H3: Gesamtpreis | I3: Nachlass | J3: Preis nach Nachlass | K3: MwSt.
A4: Leistungsbeschreibung | C4: 2022-02 Rheinberger Straße / Mühlenstraße Stadt Moers 2021-008
A5: Hinweistext | C5: Deckblatt_Stadt_Moers_und_ENNI | D5: Stadt Moers Fachbereich 8 - Fachdienst 8.2 - Straßen- und Verkehrsplanung und ENNI Stadt & Service Niederrhein AöR - Abteilung (LP) - Leitungsgebundene Aktivitäten Planung und Bau A n g e b o t über Straßen- und Kanalsanierung Mühlenstraße, Rheinberger Straße und Repelener Straße 1.BA -Mühlenstraße und Rheinberger Straße- | K5: ="" | M5: 996bdbb5-d876-4f8f-b35c-b8ea57e198eb
A6: Hinweistext | C6: Leistungsbeschreibung gemäß DIN 18299 | D6: Leistungsbeschreibung gemäß DIN 18299 | K6: ="" | M6: 8cf685e0-27ff-437b-988b-0d4d347fe30d
A7: Hinweistext | C7: Leistungsbeschreibung gemäß DIN 18299 | D7: Soweit in der Leistungsbeschreibung auf Technische Spezifikationen, z.B. nationale Normen, mit denen Europäische Normen umgesetzt werden, europäisch technische Bewertungen, gemeinsame technische Spezifikationen, Internationale Normen, Bezug genommen wird, werden auch ohne den ausdrücklichen Zusatz: "oder gleichwertig" immer gleichwertige Technische Spezifikationen in Bezug genommen. Digital werden dem Bieter folgende Unterlagen zur Verfügung gestellt: Leistungsbeschreibung Leistungsverzeichnis Ausführungspläne Baugrundgutachten Kampfmitteluntersuchung Verkehrskonzept Die Ausführungspläne ergänzen die vorliegenden Ausschreibungsunterlagen und sind bei der Angebotskalkulation vollständig zu berücksichtigen. Das im GAEB-Format verfügbare Leistungsverzeichnis wird dem Bieter zur Vereinfachung der Kalkulation zur Verfügung gestellt. Das Leistungsverzeichnis wurde vor Bereitstellung von der Stadt Moers hinsichtlich Fehlerhaftigkeit und Vollständigkeit geprüft. Sollten zwischen der pdf-Datei und der LV-Version im GAEB-Format dennoch Differenzen bestehen, so sind daraus keine Rechtsansprüche gegen die Stadt Moers bzw. ENNI Stadt & Service Niederrhein AöR abzuleiten. Es geht immer die übermittelte pdf-Datei der Ausschreibung rechtsverbindlich in die Wertung ein. Grundlage des zu schließenden Vertrags zwischen der Stadt Moers bzw. ENNI Stadt & Service Niederrhein AöR und dem zu beauftragenden Bieter ist die zum Zeitpunkt des Vertragsschlusses gültige Fassung der VOB/B und VOB/C. Die ZTV unter Punkt vier werden ebenfalls Vertragsbestandteil. | K7: ="" | M7: ba21e7ac-a2d6-470d-b9a2-9b4ac0f3f376
A8: Hinweistext | C8: 1. Angaben zur Baustelle | D8: 1. Angaben zur Baustelle | K8: ="" | M8: 525c6792-deb3-4538-8f1d-c3073714d80f
A9: Hinweistext | C9: 1.1 Lage der Baustelle, Umgebungsbedingungen, Zufahrtsmöglichkeiten | D9: 1.1 Lage der Baustelle, Umgebungsbedingungen, Zufahrtsmöglichkeiten, Einschränkungen Bei der Baumaßnahme handelt es sich um eine Straßen- und Kanalsanierungsmaßnahme der Straßen "Mühlenstraße und Rheinberger Straße". In beiden Straßen wird der gesamte Querschnitt (Fahrbahn + Nebenflächen) neu hergestellt, zusätzlich finden in diesen beiden Straßen Kanalsanierungen im Bereich der SW- und NW-Kanäle sowie im Bereich der Anschlussleitungen statt. Die genaue Lage ist aus dem Übersichtslageplan ersichtlich. Der Übersichtsplan liegt den Ausschreibungsunterlagen bei. | K9: ="" | M9: 600c3669-b445-46d7-b590-c8c7614ca62e
A10: Hinweistext | C10: 1.2 Besondere Belastungen aus Immissionen sowie bes. klimatische oder betriebliche Bedingungen | D10: 1.2 Besondere Belastungen aus Immissionen sowie bes. klimatische oder betriebliche Bedingungen Besondere Belastungen aus Immissionen sowie besondere klimatische oder betriebliche Bedingungen sind nicht bekannt. | K10: ="" | M10: 26b0ae1b-b92a-48c0-9a07-59d2c121c69a
A11: Hinweistext | C11: 1.3 Art und Lage der baulichen Anlagen | D11: 1.3 Art und Lage der baulichen Anlagen Gegenstand der Baumaßnahme ist die Erneuerung von Schmutz- und Regenwasserkanälen sowie die Erneuerung von öffentlichen Verkehrsflächen im Bereich der Mühlenstraße und Rheinberger Straße. Dabei sind insbesondere folgende Bauleistungen zu erbringen: DIN 18.300 Erdarbeiten DIN 18.301 Bohrarbeiten DIN 18.303 Verbauarbeiten DIN 18.305 Wasserhaltungsarbeiten DIN 18.306 Entwässerungskanalarbeiten DIN 18.317 Verkehrswegebauarbeiten, Oberbau aus Asphalt DIN 18.318 Verkehrswegebauarbeiten, Pflasterdecken DIN 18.329 Verkehrssicherungsarbeiten DIN 18.330 Maurerarbeiten DIN 18.331 Betonarbeiten Die Arbeiten haben etwa folgenden Umfang: 2246 m² Aufbruch bit. befestigte Straßenflächen, bis 15 cm 1723 m² Aufbruch bit. befestigte Straßenflächen, bis 30 cm 679 m³ Aufbruch Tragschicht, bis 22 cm, nach EBV 628 m Bordsteinanlage abbrechen und entsorgen 634 m Rinnenanlage abbrechen und entsorgen 762 m² Betonsteinpflaster aufnehmen und entsorgen 779 m² Gehwegplatten aufnehmen und entsorgen 652 m vorhandenen Kanäle abbrechen und entsorgen 15 m³ vorhandene Kanäle verdämmen 33 m vorhandene Kanalschächte abbrechen und entsorgen 647 m² Waagerechter Normverbau Anschlussleitungen 740 m² Waagerechter Normverbau Hauptkanäle 2660 m² Verbau mit Grabenverbaugerät 175 m² Stirnverbau 2288 m³ Grabenaushub 285 m Kanal DN/OD 160 PP 109 m Kanal DN 250 STZ 114 m Kanal DN 400 B 128 m Kanal DN 600 B 47 m Kanal DN 700 B 7 Stck Kanalschacht DN 1000 B 1 Stck Kanalschacht DN 1200 B 1 Stck Kanalschacht DN 1500 B 703 m² Schotter zur temporären Befestigung von Kanalgräben 17 Stck Straßenablauf 650 m Rinnenanlage 511 m Bordsteinanlage 1018 m³ Frostschutzkies 1042 m³ Schottertragschicht 2822 m² Verkehrsfläche aus Asphalt 2071 m² Verkehrsfläche aus Betonsteinpflaster Die Lage der baulichen Anlagen ist in den Ausführungsplänen angegeben. Gegenstand der Baumaßnahme ist der Neubau des vorhandenen Trennsystems der Kanalisation mit Hausanschlussleitungen inkl. provisorischer Herstellung der Straßenoberfläche (30 cm Auffüllungen und 20 cm Tragschichtmaterial sowie 10 cm Tragdeckschicht), sowie Straßensanierungsmaßnahmen. Im Rahmen der Straßensanierung werden die Fahrbahnen inklusive Nebenflächen neu hergestellt. Für den Ausbau der neu herzustellenden Verkehrsflächen in Asphaltbauweise ist für die genannten Straßen die Belastungsklasse Bk 10 maßgebend, der Oberbau erfolgt in Anlehnung an die RStO 12, Belastungsklasse 10 Tafel 1, Zeile 3 mit folgendem Oberbau: 4,0 cm Asphaltdeckschicht 8,0 cm Asphaltbinderschicht 10,0 cm Asphalttragschicht 20,0 cm Schottertragschicht 23,0 cm Frostschutzschicht 65,0 cm Gesamtaufbau Für den Ausbau der neu herzustellenden Bushalteflächen in Asphaltbauweise ist die Belastungsklasse Bk 32 maßgebend, der Oberbau erfolgt in Anlehnung an die RStO 12, Belastungsklasse 32 Tafel 1, Zeile 3 mit folgendem Oberbau: 3,0 cm Asphaltdeckschicht 9,0 cm Asphaltbinderschicht 14,0 cm Asphalttragschicht 20,0 cm Schottertragschicht 29,0 cm Frostschutzschicht 75,0 cm Gesamtaufbau Für den Ausbau der neu herzustellenden Nebenflächen in Pflasterbauweise erfolgt der Oberbau, falls es erforderlich ist diesen neu herzustellen, in Anlehnung an die RStO 12, Tafel 6, Zeile 1 mit folgendem Oberbau: 8,0 cm Betonsteinpflaster 4,0 cm Bettung 15,0 cm Schottertragschicht 13,0 cm Frostschutzschicht 40,0 cm Gesamtaufbau Für den Ausbau der neu herzustellenden Schwerlastzufahrten in Pflasterbauweise erfolgt der Oberbau, falls es erforderlich ist diesen neu herzustellen, in Anlehnung an die RStO 12, Tafel 6, Zeile 1 mit folgendem Oberbau: 8,0 cm Betonsteinpflaster 4,0 cm Bettung 20,0 cm Schottertragschicht 28,0 cm Frostschutzschicht 60,0 cm Gesamtaufbau | K11: ="" | M11: 188b21ae-2cb2-449a-a3bf-2d3c453b5ca5
A12: Hinweistext | C12: 1.4 Verkehrsverhältnisse auf der Baustelle, insbesondere Verkehrsbeschränkungen | D12: 1.4 Verkehrsverhältnisse auf der Baustelle, insbesondere Verkehrsbeschränkungen Das Baufeld liegt innerhalb öffentlicher Straßen. Die Baustelle ist über öffentliche Straßen erreichbar. Verkehrsbeschränkungen, die sich auf An- und Abfahrmöglichkeiten für Baustellenfahrzeuge auswirken, liegen nicht vor. Einschränkungen der Befahrbarkeit der Straßen im Baufeld infolge der Baumaßnahmen sind unter Punkt 2.2 (Besondere Erschwernisse) aufgeführt. | K12: ="" | M12: b80efa75-1c36-4a48-a6d9-06c7c3161c67
A13: Hinweistext | C13: 1.5 Für den Verkehr freizuhaltende Flächen | D13: 1.5 Für den Verkehr freizuhaltende Flächen Die Baumaßnahme ist so durchzuführen, dass Einschränkungen für den öffentlichen Verkehr auf ein Mindestmaß beschränkt werden. Wo Behinderungen unvermeidbar sind, sind geeignete Verkehrssicherungs- und -lenkungsmaßnahmen entsprechend dem abgestimmten Verkehrskonzept umzusetzen. Zur Reduzierung verkehrlicher Beeinträchtigungen ist die Maßnahme in vier aufeinanderfolgende Bauphasen untergliedert, wie im Verkehrskonzept dargestellt. Teilweise finden Arbeiten abschnittsweise oder parallel statt, z. B. der Straßenbau Rheinberger Straße (BP3) während des Kanalbaus in der Mühlenstraße (BP2). Das Verkehrskonzept wurde mit der Stadt Moers (FD 8.2 und FD 8.3), der Polizei, der Feuerwehr sowie den Verkehrsbetrieben (NIAG) abgestimmt und liegt den Ausschreibungsunterlagen bei. Es ersetzt nicht die unter Abschnitt 2.6 aufgeführten Pflichten zur Erstellung und Vorlage von Verkehrszeichenplänen und Umleitungsregelungen – diese sind durch den Auftragnehmer zusätzlich zu erbringen. Für alle Bauphasen ist aufgrund der innerstädtischen Lage und beengter Platzverhältnisse mit abschnittsweisen Sperrungen zu rechnen. Wo möglich, erfolgt die Ausführung in halbseitiger Bauweise mit einer Mindestrestfahrbahnbreite von ≥ 3,00 m. In Bauphasen mit temporärer Vollsperrung sind entsprechende Umleitungen gemäß Verkehrskonzept umzusetzen. Eine Gehwegseite ist über alle Bauphasen hinweg auf der Rheinberger Straße dauerhaft freizuhalten und begehbar zu halten. Die Grundstücke der Anwohner müssen während der gesamten Bauzeit fußläufig erreichbar sein. Die Erreichbarkeit mit Kraftfahrzeugen ist täglich vor Baubeginn und nach Bauende sicherzustellen. In Fällen, in denen dies vorübergehend nicht möglich ist, sind betroffene Anlieger frühzeitig zu informieren. Die Zugänglichkeit für Rettungsfahrzeuge, insbesondere Feuerwehrdrehleitern, muss jederzeit gewährleistet sein, besonders zu berücksichtigen sind dabei Haus-Nr. 32, 33, 34, 37, 55. Die Längen der nicht befahrbaren Abschnitte sind auf ein Maximum von 50 Metern zu beschränken. Offene Kanalbaugruben dürfen maximal 15 Meter lang sein. Die Feuerwehr muss bis zur Grubenkante andienen können. Anliegerzufahrten werden, soweit erforderlich, mit Hinweisschildern „Bitte in den fließenden Verkehr einordnen“ ausgestattet. Während der gesamten Maßnahme wird eine Baustellen-Lichtsignalanlage am Knotenpunkt Neuer Wall / Unterwallstraße / Wilhelm-Schröder-Straße vorgehalten. Diese ist koordiniert in Abhängigkeit mit der Baustellen-LSA am Knotenpunkt Rheinberger Straße / Mühlenstraße zu schalten. Dazu ist eine Abstimmung/Koordinierung mit den LSA Planern der Stadt Moers notwendig (Herr Baas (0 28 41 / 201-576 / carsten.baas@moers.de) und Herr Schlösser (0 28 41 / 201-552 / michael.schloesser@moers.de)). Zusätzlich ist ein temporärer Kreisverkehr während der gesamten Baumaßnahme im Bereich der Gabelsberger- & Seminarstraße einzurichten, die Gabelsbergerstraße wird dabei permanent gesperrt. Dieser dient zur Aufrechterhaltung des Verkehrsflusses und verhindert Rückstoß- und Wendefahrten. Die Mittelinsel wird mit Markierungen und einem Leitsystem (Bordsteinerhöhung, nicht überfahrbar) gekennzeichnet. Die Fahrbahnbreiten sind so ausgelegt, dass Busverkehr jederzeit ungehindert passieren kann. Die Verkehrssicherung obliegt dem Auftragnehmer. Der ausführende Bauunternehmer ist verpflichtet, die Feuerwehr Moers rechtzeitig per E-Mail an vb.feuerwehr@moers.de über folgende Ereignisse zu informieren: - Beginn und Einrichtung der Baustelle - Jede Änderung der Zufahrts-, Einfahrts- oder Sperrbereiche - Abschluss der Maßnahme Die Mitteilungen sind grundsätzlich mit aktuellem Übersichtsplan / Lageplan zu versehen. Beispiel: „In der kommenden Woche erfolgt eine Vollsperrung der Rheinberger Straße im Abschnitt zwischen Hausnummer 30 und 34. Zugang für Feuerwehr wird über Baerler Straße sichergestellt.“ Zusätzlich hat der ausführende Bauunternehmer die Polizei (dirgepwsued.wesel@polizei.nrw.de), Verkehrsbetriebe (NIAG: Grasshoff, Volker: volker.grasshoff@niag-online.de) sowie die Müllabfuhr (Frank Seemann: 017614744217; fseemann@enni.de / Friedel Baumann 01709137254 / fbaumann@enni.de) über die Sperrung einzelner Straßenabschnitte zu informieren. | K13: ="" | M13: 23a27da0-373c-4c63-b86b-2ea70fc48a0a
A14: Hinweistext | C14: 1.6 Nutzbarkeit von Transporteinrichtungen und Transportwegen | D14: 1.6 Art, Lage und Maße und Nutzbarkeit von Transporteinrichtungen und Transportwegen Keine Angaben. | K14: ="" | M14: e2a862de-780e-48fe-98e1-5fec04734873
A15: Hinweistext | C15: 1.7 Energieversorgung (Wasser, Strom, Abwasser) Bedingungen für das Ableiten von Abwässern | D15: 1.7 Energieversorgung (Wasser, Strom, Abwasser) Bedingungen für das Ableiten von Abwässern Der Auftragnehmer hat sich selbst über Lage, Art, Anschlusswert und Bedingungen für das Überlassen von Anschlüssen für Wasser und Strom zu erkundigen. Die Kosten für die Herstellung der Energieversorgung sowie für den Energieverbrauch sind in die Einheitspreise einzukalkulieren. Zur Entnahme des Wassers aus Hydranten dürfen nur Standrohre der ENNI Energie & Umwelt Niederrhein GmbH benutzt werden. Aufstauungen ohne vorherige Genehmigung des Kanalnetzbetriebes (Abteilung Technische Dienste Entwässerung) der ENNI AöR sind untersagt. Ansprechperson TEW: Yvonne Schwabe, Tel.: 0 28 41 – 104 - 763, E-mail: yschwabe@enni.de Im Falle von auftretenden Ereignissen ist außerhalb der Geschäftszeiten die ENNI Ingenieurbereitschaft unter 0160 - 90 14 11 01 zu kontaktieren. | K15: ="" | M15: e38c72b1-990b-416a-a84c-b9da77f033a6
A16: Hinweistext | C16: 1.8 Vom Auftraggeber zur Verfügung gestellte Flächen und Räume | D16: 1.8 Vom Auftraggeber zur Verfügung gestellte Flächen und Räume Der Auftraggeber stellt keine Flächen oder Räume zur Verfügung. Der Baubereich umfasst die Flächen der geplanten Bauwerke und die Bewegungsflächen für die zur Herstellung erforderlichen Baufahrzeuge und Geräte. Innerhalb des Baubereichs sollen sich nur die für die Bauarbeiten zwingend örtlich benötigten Teile der Baustelleneinrichtung und Materiallagerplätze befinden. Lager- und Arbeitsplätze innerhalb des Baubereichs entstehen entsprechend dem Bauablauf räumlich und zeitlich begrenzt am aktuellen Bauort. Alle übrigen Teile der Baustelleneinrichtung und Materiallagerplätze befinden sich außerhalb des Baubereichs. Hierzu gehören insbesondere Material- und Gerätecontainer, Lagerräume, Zwischenlagerfläche für separierten Boden mit unklarer Schadstoffbelastung, Waschräume, Toilettenanlage, Aufenthaltsräume, Baubüro, Anschlüsse für Strom und Wasser, sonstige Lager- und Arbeitsplätze, Verkehrssicherung und Schilder. Zusätzlich benötigte Flächen und Räume hat sich der Auftragnehmer rechtzeitig vor Baubeginn zu beschaffen, für die Dauer der Baumaßnahmen zu unterhalten und nach Beendigung der Arbeiten zu räumen. Die Genehmigung für die Nutzung von Flächen ist rechtzeitig vor Baubeginn von den Eigentümern einzuholen. Die Kosten sind in die Einheitspreise einzukalkulieren. Ansprechpartner für die Flächennutzungsplanung der Stadt Moers: Herr Sell Tel: 02841/201-416 Mail: Pascal.Sell@Moers.de | K16: ="" | M16: 7cef0235-9eeb-470b-b281-4a31820e5ad3
... A32: Hinweistext | C32: 2 Angaben zur Ausführung | D32: 2 Angaben zur Ausführung | K32: ="" | M32: 490bbd59-1bef-40c9-a8e5-5c6f0a6e4d3c
A33: Hinweistext | D33: 2.1 Bauablauf (Arbeitsabschnitte, -unterbrechungen und –beschränkungen) Der Bauablauf ist mit der Bauüberwachung der ENNI abzustimmen. Der Baubeginn ist verbindlich in der 14. KW 2026 vorzusehen. Vor Baubeginn erfolgt eine Standortbegehung gemeinsam mit der örtlichen Bauüberwachung / Bauoberleitung des AG. Arbeitsunterbrechungen sind nicht vorgesehen. Das Verkehrskonzept sieht die Aufteilung der Baumaßnahme in 4 Bauphasen vor: Bauphase 1: Kanalbau Rheinberger Straße Bauphase 2: Kanalbau Mühlenstraße Bauphase 3: Straßenbau Rheinberger Straße Bauphase 4: Straßenbau Mühlenstraße Bauphasenbeschreibung Bauphase 1 Der Baustart erfolgt im Kreuzungsbereich Rheinberger Straße/Mühlenstraße. Aufgrund der Lage des Kanals ist eine Vollsperrung notwendig. Die Arbeiten erfolgen von Süd nach Nord in Richtung Baerler Straße. Die Bauarbeiten sind so aufzuführen, dass die Erreichbarkeit der Hausnummern 36 bis 40 und die Andienung der Hausnummern 32, 33, 34, 37 und 55 mit Drehleiter sichergestellt ist. Eine Gehwegseite bleibt durchgängig begehbar. Neben den Arbeiten der ENNI beabsichtigt die Fernwärme Niederrhein die Herstellung von zwei Hausanschlüsse (bei Rheinberger Straße 41 und 49) in der ersten Bauphase. Abstimmungen zu den Arbeiten sind direkt mit der Fernwärme Niederrhein zu treffen (Kontaktdaten siehe Punkt 1.20). Die vorhandenen Senkenleitungen werden im Kanalgraben provisorisch mitgeführt und im Zuge des Straßenbaus neu angeschlossen. Der Kanalbau umfasst SW- und RW-Leitungen mit provisorischen und späteren endgültigen Anschlüssen. Der Schacht 32192S101 bildet den Übergabepunkt für das Provisorium aus der Mühlenstraße. Der Bau erfolgt gegen die Fließrichtung. Die Verbindung zur Baerler Straße bleibt möglichst lange offen. Die Arbeiten an der Kreuzung sollen innerhalb von 5 Wochen abgeschlossen sein, um die Verbindung Richtung Süden wiederherzustellen. Bauphase 2 Nach Abschluss der Kanalbauarbeiten in der Rheinberger Straße beginnt die Kanalbaukolonne mit dem Bau des SW-Kanals in der Mühlenstraße. Die Arbeiten starten im Kreuzungsbereich und verlaufen gegen die Fließrichtung Richtung Brücke. Bestehende Provisorien werden aufgenommen und ordnungsgemäß eingebunden. Der Bestandsschacht 32192S001 entfällt. Der RW-Kanal folgt im Anschluss, beginnend am Bestandsschacht 32192R206, dessen Anschluss angepasst wird. Die vorhandenen Senkenleitungen werden provisorisch mitgeführt. Während dieser Bauphase erfolgt bereits der Straßenbau Rheinberger Straße (Bauphase 3a) parallel. Der Zufahrt für Rettungsfahrzeuge ist zu jeder Zeit sicherzustellen.Eine Gehwegseite bleibt durchgängig begehbar. Bauphase 3 Nach Abschluss der Kanalbauarbeiten im Kreuzungsbereich Rheinberger/Mühlenstraße beginnt der Straßenbau in der Rheinberger Straße. Die Arbeiten erfolgen in drei Abschnitten (3a Westseite, 3b/3c Ostseite) in halbseitiger Bauweise. Eine Vollsperrung ist nicht vorgesehen. Der Verkehr wird während der gesamten Bauphase 3 als Einbahnstraße in Fahrtrichtung „stadtauswärts“ geführt. Südlich des KP Mühlenstraße / Rheinberger Straße ist eine Bedarfs-LSA für Fußgänger einzurichten. Damit Einsatzfahrzeuge und der ÖPNV entgegen der Einbahnstraße in Fahrtrichtung „stadteinwärts“ die Rheinberger Straße befahren können, ist nördlich des Baufeldes ein zusätzlicher Signalgeber vorzusehen. Dieser ist mit der südlichen Bedarfs-LSA zu koppeln. Jede Zufahrt im Baufeld ist mit einem Signalgeber auszustatten.In Bauphase 3c ist der Knotenpunkt Mühlenstraße / Rheinberger Straße mit einer Baustellen-LSA auszustatten. Diese ist weiterhin mit dem nördlichen Signal für Rettungsfahrzeuge und ÖPNV zu koppeln. Die Baumaßnahme ist so zu gestalten, dass eine durchgehende Restfahrbahnbreite ≥ 3,00 m gewährleistet wird. Die Bauarbeiten sind so aufzuführen, dass die Erreichbarkeit der Hausnummern 36 bis 40 und die Andienung der Hausnummern 32, 33, 34, 37 und 55 mit Drehleiter sichergestellt ist. Eine Gehwegseite bleibt durchgängig begehbar. Bauphase 4 Nach Abschluss der Arbeiten in Rheinberger Straße sowie des Kanalbaus in der Mühlenstraße erfolgt der Straßenbau in der Mühlenstraße. Auch hier erfolgt die Ausführung in zwei Teilabschnitten (Süd- und Nordseite) in halbseitiger Bauweise unter Aufrechterhaltung des Verkehrs mit LSA-Führung. Die Baufelder sind so zu wählen, dass die Zufahrt für Rettungsfahrzeuge jederzeit möglich sind. Anliegerzufahrten sind mit einem Hinweisschild "Bitte in den fließenden Verkehr einordnen" auszustatten. Eine Gehwegseite bleibt durchgängig begehbar. | K33: ="" | M33: 73562370-a84c-4136-9cbc-47b18baf6cce
A34: Hinweistext | C34: 2.2 Besondere Erschwernisse während der Ausführung, z.B. Arbeiten im Bereich von Verkehrswegen | D34: 2.2 Besondere Erschwernisse während der Ausführung, z.B. Arbeiten im Bereich von Verkehrswegen Verkehr: Den Anliegern ist die Erreichbarkeit der Grundstücke zu ermöglichen (insbesondere Rettungsfahrzeuge, Müllabfuhr, Anwohner, Lieferanten), siehe Punkt 1.5. Sollte dies temporär, aufgrund des Baufortschrittes, nicht möglich sein ist der AN angehalten dies mit den jeweiligen Anwohnern abzustimmen. Zumindest zum Feierabend müssen die Grundstücke anfahrbar sein. Dies ist ggf. durch das Verlegen von Stahlplatten oder das Herstellen von Anrampungen sicherzustellen. Eine fußläufige Erreichbarkeit der Grundstücke muss über den Zeitraum der Baumaßnahme gewährleistet werden. Müllabfuhr: Der AN hat während der Baumaßnahme der ENNI als Abfallentsorger die Zuwegung zu den Anliegern zu ermöglichen. Wird dies durch den Bauablauf behindert, so hat der AN mit der ENNI einen Übergabepunkt für die zu leerenden Mülltonnen festzulegen sowie den Hin- und Rücktransport der Mülltonnen (Restmülltonne, Blaue Tonne, Biotonne) sowie gelber Säcke/gelbe Tonne und Grünschnitt zu organisieren. Die jeweiligen Abfuhrtermine können auf der Webseite http://www.enni.de/stadt-service/abfall/abfallkalender eingesehen werden. Ansprechpartner ENNI Stadt und Service: Friedel Baumann: Tel. 01709137254 / Mail: fbaumann@enni.de Frank Seemann: Tel. 017614744217 / Mail: fseemann@enni.de Überleitung von Abwasser aus Kanälen: Während der gesamten Bauphase ist der Abwasserabfluss aufrecht zu erhalten. Bei Regenwetter ist in den Kanälen mit großen Abwassermengen und Einstau der Kanäle bis maximal zur Geländeoberkante zu rechnen. Wird ein vorhandener Kanal abgebrochen, so ist der Abwasserzufluss von oberhalb provisorisch überzuleiten und sämtliche Straßenablauf- und Hausanschlusskanäle bis zum endgültigen Anschluss an den neuen Kanal provisorisch zu übernehmen. Beim Anschluss an vorhandene Kanäle oder an den vorhandenen Graben ist die Baugrube gegen Rückstau zu sichern. Dabei ist die vorhandene Geländeoberkante als Rückstauebene anzunehmen. Die Überleitungs- und Sicherungsmaßnahmen sind entsprechend druckdicht auszuführen. Kanalgraben: Die Länge des offenen Kanalgrabens ist auf 15 m zu begrenzen. Die Feuerwehr muss die Grube jederzeit bis zur Kante anfahren können. Verfüllte Grabenabschnitte sind bis zur endgültigen Wiederherstellung der Straßenoberfläche provisorisch verkehrssicher zu befestigen und zu unterhalten. Lager- und Arbeitsplätze außerhalb des Baufeldes: Innerhalb des Baufeldes dürfen sich nur die für die Bauarbeiten zwingend örtlich benötigten Teile der Baustelleneinrichtung und Materiallagerplätze befinden. Lager- und Arbeitsplätze innerhalb des Baufeldes entstehen entsprechend dem Bauablauf räumlich und zeitlich begrenzt am aktuellen Bauort. Alle übrigen Teile der Baustelleneinrichtung und Materiallagerplätze dürfen sich nicht im Bereich des Baufeldes befinden. Kanaluntersuchung durch den Kanalnetzbetrieb der ENNI Stadt & Service Niederrhein AöR innerhalb der Bauzeit: Der Kanalnetzbetrieb der ENNI Stadt & Service Niederrhein AöR wird innerhalb der Bauzeit die fertiggestellten Kanäle untersuchen, siehe Punkt 2.1. Der Auftragnehmer hat diese Arbeiten zu dulden und selbst rechtzeitig eine Abstimmung mit dem Kanalnetzbetrieb der ENNI Stadt & Service Niederrhein AöR vorzunehmen. Die Kosten für die genannten besonderen Erschwernisse sind in die Einheitspreise einzukalkulieren, sofern sie nicht in Einzelpositionen des Leistungsverzeichnisses enthalten sind. | K34: ="" | M34: 64c94dab-9bb2-4c78-b8ab-5c5913adb3f3
A35: Hinweistext | C35: 2.3 Bauzeitenplan | D35: 2.3 Bauzeitenplan Für die gesamten geplanten Baumaßnahmen ist ein Bauzeitenplan zu erstellen (eine entsprechende Position ist Bestandteil des Leistungsverzeichnisses). Wenn unter Punkt 2.1 nichts Anderes ausdrücklich erwähnt ist, obliegt die Planung des Bauablaufes dem Ermessen des Auftragnehmers. Die detaillierten Ausführungstermine sind mit der örtlichen Bauüberwachung der ENNI und dem Verkehrssicherungsunternehmen abzustimmen. Beim Aufstellen des Bauzeitenplans sind alle Gewerke zu berücksichtigen. Die Darstellung hat mit einem Zeitraster von mindestens einer Woche zu erfolgen. Jeweils nach vier Wochen Bauzeit ist der Plan zu erneuern und der AG-Bauüberwachung vorzulegen. Der neue Bauzeitplan muss eine Darstellung des Soll-Ist-Vergleichs enthalten. Der erste Bauzeitenplan ist fünf Werktage vor Arbeitsbeginn unaufgefordert dem Bauüberwacher des AG zu übergeben. | K35: ="" | M35: bb12a4fc-7a50-4a50-b4b7-575c92365a36
A36: Hinweistext | C36: 2.4 Besondere Anforderungen für Arbeiten in kontaminierten Bereichen | D36: 2.4 Besondere Anforderungen für Arbeiten in kontaminierten Bereichen Es sind keine Schadstoffbelastungen im Baufeld bekannt, siehe Punkt 1.21. Besondere Anforderungen für die Arbeiten sind nicht vorgesehen. | K36: ="" | M36: 7eb8cbc5-9bda-48a7-8b3a-b37787fda4f5
A37: Hinweistext | C37: 2.5 Besondere Anforderungen an die Baustelleneinrichtung / Entsorgungseinrichtungen | D37: 2.5 Besondere Anforderungen an die Baustelleneinrichtung / Entsorgungseinrichtungen Besondere Anforderungen an die Baustelleneinrichtung können sich aus umweltrechtlichen Anforderungen ergeben (siehe Abschnitt 1.11). Die erforderlichen Ausrüstungen, Geräte und PSA sind Bestandteil der Baustelleneinrichtung und in den Einheitspreis einzukalkulieren. | K37: ="" | M37: 4db8584a-045a-46a4-9273-0479f6ad3f8b
A38: Hinweistext | C38: 2.6 Besonderheiten der Regelung und Sicherung des Verkehrs | D38: 2.6 Besonderheiten der Regelung und Sicherung des Verkehrs Die Sicherung des Verkehrs erfolgt durch den Auftragnehmer.Erforderliche Genehmigungen sind durch den AN einzuholen. Die Kosten hierfür sind in die Einheitspreise einzukalkulieren. Spätestens 4 Wochen vor Ausführung der verkehrslenkenden Maßnahmen ist ein Verkehrsführungs- und Beschilderungsplan in anordnungsfähiger Ausführung anzufertigen und bei dem zuständigen Fachdienst 8.3 - Straßen- und Verkehrsrecht der Stadt Moers einzureichen. Die Erstellung der Verkehrssicherungspläne hat in digitaler Form zu erfolgen. Die Sicherung des Verkehrs hat nach Vorgabe des Fachdienstes 8.3 - Straßen- und Verkehrsrecht durch ein fachlich qualifiziertes Unternehmen zu erfolgen. Erforderliche Genehmigungen sind durch den AN einzuholen. Die Kosten hierfür sind in die Einheitspreise einzukalkulieren. Die Planung der Beschilderung sowie die Abstimmung mit der ENNI Stadt & Service Niederrhein AöR, Nahverkehrsunternehmen, Feuerwehr, Rettungsdienste, Polizei und Entsorgungsunternehmen sind durch den AN durchzuführen. Auflagen der Behörden sind zu befolgen. Baustellen an oder in öffentlichen Verkehrsflächen sind durch stabile, entsprechend der Straßenverkehrsordnung rot-weiß gestreifte Absperrschranken nach ZTV-SA und RSA abzusichern. Die Kosten hierfür sind in die LV-Positionen einzurechnen. Zu beachten ist die Gebührenordnung für Anordnungen nach § 45 Abs. 6 StVO über Maßnahmen der Unternehmer im Straßenverkehr. Folgende Gebühren werden erhoben: für die Dauer von 1 Tag: 35,00 €, bei Verlängerung je Tag: 15,00 €; 2 Tage bis 1 Woche: 50,00 €, bei Verlängerung je Woche: 25,00 €; bis zu 3 Wochen: 100,00 €, bei (jeder) Verlängerung: 50,00 €; bis zu 6 Wochen: 150,00 €, bei (jeder) Verlängerung: 100,00 €; über 6 Wochen: 250,00 €, bei (jeder) Verlängerung: 100,00 €; über 3 Monate: 500,00 € bei (jeder) Verlängerung: 150,00 €; über 6 Monate: 767,00 € Zusätzlich zu a) –g) wenn ein Ortstermin erforderlich ist: 110,00 € Verwaltungsaufwand je angefangene Viertelstunde: 16,25 € Fahrtkosten je Kilometer: 0,30 € Eilzuschlag zusätzlich zu a) – e) (außer bei unvorhergesehenen Notfallarbeiten) wenn der Antrag - innerhalb von 2 Wochen vor Beginn der Arbeiten gestellt wird: - 25 % der Grundgebühr - innerhalb von 1 Woche vor Beginn der Arbeiten gestellt wird: - 50 % der Grundgebühr Nachkontrolle aufgrund von Mängeln: 50,00 € Das Außerkraftsetzen von Verkehrszeichen durch Klebebänder ist verboten. Bei Zuwiderhandlungen ist Ersatz für beschädigte Schilder zu leisten. Es können Schilderhüllen, Jute- oder Plastiksäcke verwendet werden. Wegweiser sind durch ein rotes Holzlattenkreuz in Abstimmung mit der Bauüberwachung außer Kraft zu setzen. Zu beachten ist, dass ein zertifiziertes Fachunternehmen die Verkehrssicherung durchführt. | K38: ="" | M38: 7b9fe972-fba3-4bf7-88df-76337518e90c
A39: Hinweistext | C39: 2.7 Besondere Anforderungen an das Auf- und Abbauen sowie Vorhalten von Gerüsten | D39: 2.7 Besondere Anforderungen an das Auf- und Abbauen sowie Vorhalten von Gerüsten Der Einsatz von Gerüsten, die keine Nebenleistung sind, ist nicht vorgesehen. | K39: ="" | M39: c27e5808-21a2-42cb-abe6-98247f9f3e16
A40: Hinweistext | C40: 2.8 Mitbenutzung fremder Gerüste, Hebezeuge, Aufzüge, Geräte, Einrichtungen und dergleichen | D40: 2.8 Mitbenutzung fremder Gerüste, Hebezeuge, Aufzüge, Geräte, Einrichtungen und dergleichen Nicht vorgesehen. | K40: ="" | M40: d1eadb5e-9c93-4879-b0a8-5d62d3980dec
A41: Hinweistext | C41: 2.9 Mitbenutzung eigener Geräte, Einrichtungen o. ä. durch Dritte; Dauer und Arbeiten | D41: 2.9 Mitbenutzung eigener Geräte, Einrichtungen o. ä. durch Dritte; Dauer und Arbeiten Nicht vorgesehen. | K41: ="" | M41: f9e3f3a9-6203-4169-9a0d-a9ecbc482e2d
A42: Hinweistext | C42: 2.10 Verwendung oder Mitverwendung von wiederaufbereiteten (Recycling-) Stoffen | D42: 2.10 Verwendung oder Mitverwendung von wiederaufbereiteten (Recycling-) Stoffen Wiederaufbereitetes Material darf nur verwendet werden, wenn die Verwendung im Positionstext beschrieben wird. | K42: ="" | M42: 786ceb22-c93b-4af4-ad91-b85f76bc5f64
A43: Hinweistext | C43: 2.11 Anforderungen an wiederaufbereitete (Recycling-)Stoffe und nicht genormte Stoffe und Bauteile | D43: 2.11 Anforderungen an wiederaufbereitete (Recycling-)Stoffe und nicht genormte Stoffe und Bauteile Es sind mit Ausnahme der ausgeschriebenen Recycling-Baustoffe grundsätzlich neuwertige Baustoffe einzubauen. | K43: ="" | M43: 2cfdc6f0-e3e7-4630-8d35-cdc2456d7151
A44: Hinweistext | C44: 2.12 Besondere Anforderungen an Art, Güte und Umweltverträglichkeit der Stoffe und Bauteile | D44: 2.12 Besondere Anforderungen an Art, Güte und Umweltverträglichkeit der Stoffe und Bauteile Siehe Vorbemerkungen und Positionstexte im LV zu Stoffen und Bauteilen. Beim Bau von Einsteigschächten aus Betonfertigteilen ist die Fugenzahl durch die Verwendung von Schachtringen größtmöglicher Bauhöhe zu minimieren. Zwischen Konus und Schachtabdeckung ist mindestens ein Ausgleichsring vorzusehen. | K44: ="" | M44: 94d4a85a-4e8b-45e8-bb50-6ba0b352e590
A45: Hinweistext | C45: 2.13 Art und Umfang der vom Auftraggeber verlangten Eignungs- und Gütenachweise | D45: 2.13 Art und Umfang der vom Auftraggeber verlangten Eignungs- und Gütenachweise Allgemeines: Eignungs- und Gütenachweise sind vollständig und nachvollziehbar zu dokumentieren. Die Dokumentation ist der Bauüberwachung zu übergeben. Probenahmen zur Eigenkontrolle, Bodenuntersuchungen und Prüfungen sind durch eine unabhängige Prüfstelle durchzuführen. Sämtliche hiermit verbundenen Kosten sind in die Einheitspreise einzukalkulieren, soweit sie nicht in Einzelpositionen beschrieben sind. Bodenverdichtung: Nachweis der Verdichtung im tiefen Bereich: Durch Sondierung mit der leichten Rammsonde nach DIN EN ISO 22476-2 (DPL 10) ist die Verdichtung des verfüllten Bodens im tiefen Bereich zu bestimmen. Einzuhalten sind die Grenzwerte der DIN EN ISO 22476-2 und der ZTV-E-StB 17.Ferner muss die erreichte Verdichtung mit der statischen Berechnung der Rohrleitungen übereinstimmen. Je angefangener 50 m Rohrgrabenlänge ist ein Nachweis zu führen. Die Vergütung erfolgt über Einzelpositionen des Leistungsverzeichnisses. Nachweis der Verdichtung im oberflächennahen Bereich: Durch Plattendruckversuch nach DIN 18134 ist die Verdichtung des verfüllten Bodens im oberflächennahen Bereich zu bestimmen. Einzuhalten sind die Grenzwerte nach RStO 12 für die jeweiligen Belastungsklassen, sowie nach ZTV Asphalt-StB 07/13, Normungen jeweils in der derzeit gültigen Fassung. Die Vergütung erfolgt über Einzelpositionen des Leistungsverzeichnisses. Dichtheitsprüfungen: Die Dichtheitsprüfungen von Freigefälleleitungen und Anschlussleitungen werden durch den AG durchgeführt. Nachbesserung, Wiederholung von Eignungs- und Gütenachweisen: Erfüllen Bauteile nicht die geforderten Eignungs- und Gütenachweise, sind Nachbesserungsmaßnahmen mit der Bauüberwachung abzustimmen. Nach erfolgter Nachbesserung sind die für die Eignungs- und Gütenachweise erforderlichen Probenahmen, Bodenuntersuchungen und Prüfungen zu wiederholen. Die Kosten für die Nachbesserungsmaßnahmen und die Wiederholung von Eignungs- und Gütenachweisen trägt der Auftragnehmer. | K45: ="" | M45: c14af6f9-4262-41d7-be11-ca08bc14d358
... A74: Hinweistext | C74: Vorbemerkungen (4. Zusätzliche Technische Vorschriften für die Verlegung von Entwässerungskanälen) | D74: 4. Zusätzliche Technische Vorschriften für die Verlegung von Entwässerungskanälen Richtung und Höhenlage (Ergänzungen zur DIN EN 1610) a) Die Höhenlage der Leitung ist vor dem Einbau der oberen Bettungsschicht vom AN als Eigenüberwachungsprüfung mittels Nivellement am Endpunkt sowie den 1/5 Punkten der Haltung zu kontrollieren. Das Nivellement ist von der Bauüberwachung der ENNI Stadt & Service Niederrhein AöR gegenzuzeichnen. Ebenso ist die Flucht der Haltung zwischen den angebundenen Schächten zu überprüfen. b) Bei Abweichungen der Ist-Neigung von der Soll-Neigung von mehr Gefälle der Haltung maximal zulässige Abweichung des Gefälles um I ≥ 0,3 % 0,05 Prozentpunkte 0,2 ≤ I< 0,3 % 0,04 Prozentpunkte 0,1 ≤ I< 0,2 % 0,03 Prozentpunkte I< 0,1 % 0,01 Prozentpunkte kann die ENNI Stadt & Service Niederrhein AöR die Auswechselung der Haltung und Herstellung der geforderten Sohlhöhen und Gefälleverhältnisse verlangen. Bei einem Verzicht wird eine Wertminderung im Verhältnis der tatsächlichen Leistungsfähigkeit zur theoretischen Leistungsfähigkeit bei Vollfüllung nach Prandtl-Colebrook errechnet. Berechnungsgrundlage sind die Baukosten der Haltung einschließlich der angebundenen Schächte. Baukosten, die nicht dieser oder anderen Haltungen oder Schächten zuzuordnen sind, wie Baustelleneinrichtung, Beschilderung, Verkehrssicherung, Stundenlohn etc., sind anteilig auf die Haltungslänge zu verteilen. Beispiel: a) Gefälle Soll: 0,5 % Gefälle lt. Abnahme = 0,46 % ist in Ordnung Gefälle lt. Abnahme = 0,43 % mangelbehaftet b) Gefälle: Soll 0,15 % Gefälle lt. Abnahme = 0,13 % ist in Ordnung Gefälle lt. Abnahme = 0,11 % mangelbehaftet c) Die Höhenangaben der Ausführungspläne sind einzuhalten. Mehrkosten durch vom AN zu verantwortenden Mehrtiefen werden nicht vergütet. Bei Mehr- oder Mindertiefen behält die ENNI Stadt & Service Niederrhein AöR sich Schadenersatz vor. | K74: ="" | M74: f3436363-932c-4a87-841f-52b1a6194cff
A75: Gruppe | B75: 1. | C75: Teil 1: Allgemeine Leistungen | K75: =""
A76: Gruppe | B76: 1.1. | C76: Vorbereitende Maßnahmen | K76: =""
A77: Gruppe | B77: 1.1.1. | C77: Baustelleneinrichtungsarbeiten | K77: =""
A78: Hinweistext | C78: Allgemeine Hinweise | D78: Alle, über die gesamte Bauzeit für die Ausführung der Arbeiten notwendigen Geräte und Maschinen, Bedienungspersonal, Hilfsmittel, Ausführung und damit verbundener Nebenarbeiten sowie die Lieferung aller erforderlichen Materialien sind in die Einheitspreise der entsprechenden Positionen zur Baustelleneinrichtung und Baustellenräumung einzurechnen, wenn nicht über andere LV-Positionen gesondert vergütet. Hierzu zählen insbesondere: Herrichten, Unterhalten, Wiederherstellen von Zufahrtswegen und Lagerplätzen. Aufstellen von Tagesunterkünften, Magazinen, Werkstätten etc. Herstellen und Unterhalten von notwendigen Strom- und Wasser- anschlüssen. Überwachung der Baustelle auch an Tagen ohne Arbeitseinsatz. Aufstellen, Unterhalten und das durch den Baufortschritt bedingte Umsetzen der Verkehrssicherungseinrichtung im gesamten Baustellenbereich gemäß Verkehrsrechtlicher Anordnung nach § 45 STVO und RSA in der jeweils gültigen Fassung. Nach Fertigstellung sind die Sicherungseinrichtungen wieder zu beseitigen. An Müllabfuhrtagen sind die Müllgefäße bzw. der Sperrmüll rechtzeitig vor dem Eintreffen der Müllfahrzeuge an die von ihnen anfahrbare Stelle zu befördern. Der AN hat während der Baumaßnahme die Mülltonnen aus den nicht anfahrbaren Bereichen des Baufeldes zur Abholung durch Müllfahrzeugen bis an die anfahrbaren Bereiche hin- und zurück zu trans- portieren. Nach der Entleerung sind die Gefäße unverzüglich zurückzubringen. Betrifft Müllgefäße und Müllsäcke sämtlicher von den Bauarbeiten betroffenen Anlieger. Die betroffenen Anlieger im Bereich der Baustelle sind mindestens 10 Tage vor Arbeitsbeginn schriftlich (Briefkasteneinwurf) über Einzelheiten der Baumaßnahme zu informieren. Aufrechterhaltung des Abwasserbetriebs. Säuberung der Schächte, Straßeneinläufe und Spülung der Kanäle soweit die Verschmutzungen durch die Bautätigkeit verursacht sind. Anlegen und Beseitigen von provisorischen Zufahrten und Zuwegungen. Sofern in den Leistungsbeschreibungen nicht besonders erwähnt, sind Erdaushub, Abbruchmaterialien sowie sonstiges Räumgut auf einer geeigneten Deponie als Abfall zu entsorgen. Kosten für die Verladung, Abfuhr, Entsorgung einschl. Deponiegebühren werden nicht extra vergütet und sind in die Einheitspreise der Bodenabfuhrpositionen einzurechnen. Die Baustelle ist so herzustellen und zu unterhalten, dass der Verkehr zu jederzeit nicht übermäßig beeinträchtigt wird. Dies gilt insbesondere für Fahrzeuge der Rettungsdienste, Polizei, Feuerwehr, Müllabfuhr, öffentlicher Personennahverkehr etc. Diese Vorgabe gilt für alle Titel des Leistungsverzeichnisses. Besondere Vorgaben für den Bauablauf: Vor Baubeginn ist der Feuerwehr ein Übersichtsplan der Planung zu übergeben. Das Baufeld im Bereich der Kanalbaugruben ist auf eine Länge von ca. 15,00 m zu begrenzen. Baufahrzeuge sind nach Feierabend aus dem öffentlichen Verkehrsbereich des Baufeldes zu entfernen. Parallel stattfindende Aufbrucharbeiten / Arbeitsabläufe (z.B. zwei Kanalbaukolonnen) sind im Vorfeld mit der Feuerwehr abzusprechen. Der ausführende Bauunternehmer ist vertraglich verpflichtet, die Feuerwehr wöchentlich über den Stand der Arbeiten und den geplanten Arbeitsfortschritt per E-mail an die Adresse vb.feuerwehr@moers.de zu unterrichten. Zusätzlich hat der Auftragnehmer die Polizei, Verkehrsbetriebe sowie die Müllabfuhr über die Sperrung einzelner Straßenabschnitte zu informieren. ( Es ist zu beachten, dass für die Müllabfuhr unterschiedliche Entsorgungsbetriebe zuständig sind ). Hierzu hat er vor Beginn der Arbeiten innerhalb eines Straßenabschnittes Auskunft über den Baubereich, sowie über die voraussichtliche Dauer der Sperrung zu geben. Änderungen am Baufeld sowie Verschiebungen im Bauablauf sind der Feuerwehr, der Polizei sowie der Müllabfuhr unverzüglich nach Bekanntwerden mitzuteilen. Die Kosten für Koordination und die Erschwernis der Arbeiten in einem eingeschränkten Baufeld sind in die Positionen des Leistungsverzeichnisses mit einzurechnen und werden nicht gesondert vergütet. | K78: ="" | M78: 3dfcec69-f7fb-4edf-879d-3c768e759696
A79: Position | B79: 1.1.1.01 | C79: Baustelleneinrichtung | D79: Antransportieren, aller für die Bauausführung erforderlichen Einrichtungen, Maschinen, Geräte, Werkzeuge, Bauwagen, Lagerschuppen, Aufenthaltsräume, Abortanlagen und Zäune entsprechend der Vorschriften der Berufsgenossenschaft und der Straßenverkehrsordnung. Vom Bieter ist nach Auftragserteilung ein detaillierter Baustelleneinrichtungsplan vorzulegen. Es sind, soweit vorgesehen, darzustellen: Baustromanschluss, Bauwasseranschluss Büro-, magazin-, Aufenthaltscontainer WC- und Wascheinrichtungen Oberboden und Aushublagerplätze Die erforderlichen Ver- und Entsorgungsanschlüsse herstellen einschließlich Zähler. Beschaffen, Mieten und Anlegen notwendiger Arbeits- und Lagerflächen sowie Zufahrtswege, die über die vom AG zur Verfügung gestellten Möglichkeiten hinausgehen. Bei Bedarf Zufahrtswege zur Baustelle sowie Lagerplätze, sonstige Platzbefestigungen und Wege im Baustellenbereich anlegen. Mutterbodenarbeiten und Beseitigung des Aufwuchses für die Baustelleneinrichtung, soweit erforderlich, werden nicht gesondert vergütet. Die Kosten für Vorhalten, Unterhalten und Betreiben der Geräte, Anlagen und Einrichtungen einschließlich Mieten, Pacht, Gebühren und dgl. sind in die Einheitspreise der betreffenden Teilleistungen einzurechnen. Für Rettungsmaßnahmen in umschlossenen Räumen von abwassertechnischen Anlagen muss eine Rettungsausrüstung vorhanden sein: ein frei tragbares, von der Umgebungsatmosphäre unabhängiges Atemschutzgerät mit Vollmaske, z.B Regenerationsgerät mit Drucksauerstoff bzw. chemisch gebundenem Sauerstoff ein Abseil- und Rettungshubgerät, zwei Sicherheitsleinen und Auffanggurt eine betriebsfertige, explosionsgeschützte Handleuchte ein Verbandskasten nach DIN 12 157 "Erste Hilfe Material", Verbandskasten C eine Löscheinrichtung (z.B. Handfeuerlöscher) Gasspürgerät / Gaswarner bzw. -melder Aufstellen von Leiteinrichtungen (z.B. Leitbaken, Absperrschranken, Schrammborde etc..) einschließlich der erforderlichen Beleuchtung innerhalb der Baustelle und des dazugehörigen Bereiches gemäß den Richtlinien für die Sicherung von Arbeitsstellen auf Straßen RSA und der ZTV-SA. | E79: 1 | F79: psch | G79: =SUMPRODUCT((Kalkulation!A2:A50000=B79)*Kalkulation!D2:D50000) -> 0 | H79: =G79*E79 -> 0 | J79: =H79*(1-I79) -> 0 | K79: =B2 -> 0 | L79: 68b12ec4-df45-4506-86b5-e1f50a53d190 | M79: f47f9614-c8cb-43c5-80eb-f23c38fd8144
A80: Position | B80: 1.1.1.02 | C80: Baustelleneinrichtung vorhalten | D80: Vorhaltung aller für die Bauausführung erforderlichen Einrichtungen wie Geräte, Maschinen, Bauwagen- bzw. -container, Abortanlagen, Waschcontainer, Absperrung und Beleuchtung der Baustelle sowie der Anschlüsse von Wasser, Gas, Strom und Telefon im Bereich der Baustelle sowie Unterhaltung von Lagerflächen und Arbeitsplätzen außerhalb des Baustellenbereiches. | E80: 1 | F80: psch | G80: =SUMPRODUCT((Kalkulation!A2:A50000=B80)*Kalkulation!D2:D50000) -> 0 | H80: =G80*E80 -> 0 | J80: =H80*(1-I80) -> 0 | K80: =B2 -> 0 | L80: 68b12ec4-df45-4506-86b5-e1f50a53d190 | M80: 19e7f877-72cb-4275-8df5-7cd8755c42a6
A81: Position | B81: 1.1.1.03 | C81: Baustellenräumung | D81: Baustelle von allen Geräten, Anlagen, Maschinen, Einrichtungen und dergleichen räumen. Benutzte Flächen und Wege entsprechend dem ursprünglichen Zustand unter Wahrung der landschaftlichen Belange ordnungsgemäß herrichten. Verunreinigungen beseitigen. Der ursprüngliche Zustand der Flächen ist wieder herzustellen und vom Auftraggeber schriftlich bestätigen zu lassen. | E81: 1 | F81: psch | G81: =SUMPRODUCT((Kalkulation!A2:A50000=B81)*Kalkulation!D2:D50000) -> 0 | H81: =G81*E81 -> 0 | J81: =H81*(1-I81) -> 0 | K81: =B2 -> 0 | L81: 68b12ec4-df45-4506-86b5-e1f50a53d190 | M81: 44e61555-7690-4ce3-941c-6715321ae607
A82: Position | B82: 1.1.1.04 | C82: Bauzeitenplan | D82: Erstellung eines Bauzeitenplans für die gesamte geplante Baumaßnahme. Beim Aufstellen des Bauzeitenplans sind alle Gewerke analog dem Leistungsverzeichnis zu berücksichtigen. Die Darstellung hat mit einem Zeitraster von einer Woche zu erfolgen. Die Anzahl der Kolonnen und deren Mitarbeiter ist einzutragen. Jeweils nach vier Wochen Bauzeit ist der Plan zu erneuern und aktualisieren. Der neue Bauzeitenplan muss eine Darstellung des Soll-Ist-Vergleichs enthalten. Der erste Bauzeitenplan ist fünf Werktage vor Arbeitsbeginn unaufgefordert der Bauüberwachung des AG zu übergeben. | E82: 1 | F82: psch | G82: =SUMPRODUCT((Kalkulation!A2:A50000=B82)*Kalkulation!D2:D50000) -> 0 | H82: =G82*E82 -> 0 | J82: =H82*(1-I82) -> 0 | K82: =B2 -> 0 | L82: 68b12ec4-df45-4506-86b5-e1f50a53d190 | M82: bf829549-6556-4912-a816-30d92d88ca26
A83: Position | B83: 1.1.1.05 | C83: Baustellenschild | D83: Bauschild nach Vorgabe des AG anfertigen, liefern, aufstellen, für die gesamte Bauzeit vorhalten und wieder entfernen und entsorgen. Das Schild ist aus einem stabilen Gerüst und einer standfesten Gründung nach statisch Erfordernissen herzustellen und sturmsicher aufzustellen. Größe des Bauschildes: Hauptschild b x h = 3,00 x 2,00 m. Höhe der Schildunterkante mind. 3,0 m über Gelände Folienträger und Beschriftung in wetterfester Ausführung Vorbereitung der Aufstellfläche und Fundamentierung nach statischer Erfordernis Gerüstabmessungen und Material nach statischer Erfordernis Aufstellort in Abstimmung mit dem AG. Lieferung der Druckvorlage durch den AG. In den Einheitspreis dieser Position sind die Kosten für den statischen Nachweis einzurechnen. | E83: 1 | F83: St | G83: =SUMPRODUCT((Kalkulation!A2:A50000=B83)*Kalkulation!D2:D50000) -> 0 | H83: =G83*E83 -> 0 | J83: =H83*(1-I83) -> 0 | K83: =B2 -> 0 | L83: 68b12ec4-df45-4506-86b5-e1f50a53d190 | M83: 76629818-a470-4657-a304-4df844132a26
...

Sheet Projektinfo
A1: Projektname | B1: 2022-02_KS_Rheinberger/Mühlen
A2: Einheitspreisanteile
A4: Käufer
A5: Name
A6: Straße
A7: Postleitzahl
A8: Stadt
A9: Land
A10: Kontaktperson
A11: Email
A12: Telefon
A15: Bieter
A16: Name
... A26: Telefon

Sheet Kalkulation
A1: Ordnungszahl | B1: Kommentar | C1: Einheitspreisanteil | D1: Ergebnis | E1: Einheit | F1: 1.1.1.01
A2: 1.1.1.01 | E2: =IF(ISBLANK(A2),"",IF(ISNA(VLOOKUP(A2,'202202KSRheinbergerMühlen'!$B$4:$F$575,5,FALSE)),"",VLOOKUP(A2,'202202KSRheinbergerMühlen'!$B$4:$F$575,5,FALSE))&"") -> psch | F2: 1.1.1.02
A3: 1.1.1.02 | E3: =IF(ISBLANK(A3),"",IF(ISNA(VLOOKUP(A3,'202202KSRheinbergerMühlen'!$B$4:$F$575,5,FALSE)),"",VLOOKUP(A3,'202202KSRheinbergerMühlen'!$B$4:$F$575,5,FALSE))&"") -> psch | F3: 1.1.1.03
A4: 1.1.1.03 | E4: =IF(ISBLANK(A4),"",IF(ISNA(VLOOKUP(A4,'202202KSRheinbergerMühlen'!$B$4:$F$575,5,FALSE)),"",VLOOKUP(A4,'202202KSRheinbergerMühlen'!$B$4:$F$575,5,FALSE))&"") -> psch | F4: 1.1.1.04
A5: 1.1.1.04 | E5: =IF(ISBLANK(A5),"",IF(ISNA(VLOOKUP(A5,'202202KSRheinbergerMühlen'!$B$4:$F$575,5,FALSE)),"",VLOOKUP(A5,'202202KSRheinbergerMühlen'!$B$4:$F$575,5,FALSE))&"") -> psch | F5: 1.1.1.05
A6: 1.1.1.05 | E6: =IF(ISBLANK(A6),"",IF(ISNA(VLOOKUP(A6,'202202KSRheinbergerMühlen'!$B$4:$F$575,5,FALSE)),"",VLOOKUP(A6,'202202KSRheinbergerMühlen'!$B$4:$F$575,5,FALSE))&"") -> St | F6: 1.1.1.06
A7: 1.1.1.06 | E7: =IF(ISBLANK(A7),"",IF(ISNA(VLOOKUP(A7,'202202KSRheinbergerMühlen'!$B$4:$F$575,5,FALSE)),"",VLOOKUP(A7,'202202KSRheinbergerMühlen'!$B$4:$F$575,5,FALSE))&"") -> St | F7: 1.1.1.07
A8: 1.1.1.07 | E8: =IF(ISBLANK(A8),"",IF(ISNA(VLOOKUP(A8,'202202KSRheinbergerMühlen'!$B$4:$F$575,5,FALSE)),"",VLOOKUP(A8,'202202KSRheinbergerMühlen'!$B$4:$F$575,5,FALSE))&"") -> St | F8: 1.1.1.08
A9: 1.1.1.08 | E9: =IF(ISBLANK(A9),"",IF(ISNA(VLOOKUP(A9,'202202KSRheinbergerMühlen'!$B$4:$F$575,5,FALSE)),"",VLOOKUP(A9,'202202KSRheinbergerMühlen'!$B$4:$F$575,5,FALSE))&"") -> St | F9: 1.1.1.09
A10: 1.1.1.09 | E10: =IF(ISBLANK(A10),"",IF(ISNA(VLOOKUP(A10,'202202KSRheinbergerMühlen'!$B$4:$F$575,5,FALSE)),"",VLOOKUP(A10,'202202KSRheinbergerMühlen'!$B$4:$F$575,5,FALSE))&"") -> St | F10: 1.1.1.10
A11: 1.1.1.10 | E11: =IF(ISBLANK(A11),"",IF(ISNA(VLOOKUP(A11,'202202KSRheinbergerMühlen'!$B$4:$F$575,5,FALSE)),"",VLOOKUP(A11,'202202KSRheinbergerMühlen'!$B$4:$F$575,5,FALSE))&"") -> m2 | F11: 1.1.1.11
A12: 1.1.1.11 | E12: =IF(ISBLANK(A12),"",IF(ISNA(VLOOKUP(A12,'202202KSRheinbergerMühlen'!$B$4:$F$575,5,FALSE)),"",VLOOKUP(A12,'202202KSRheinbergerMühlen'!$B$4:$F$575,5,FALSE))&"") -> m2 | F12: 1.1.1.12
A13: 1.1.1.12 | E13: =IF(ISBLANK(A13),"",IF(ISNA(VLOOKUP(A13,'202202KSRheinbergerMühlen'!$B$4:$F$575,5,FALSE)),"",VLOOKUP(A13,'202202KSRheinbergerMühlen'!$B$4:$F$575,5,FALSE))&"") -> St | F13: 1.1.1.13
... A344: 6.3.5. | E344: =IF(ISBLANK(A344),"",IF(ISNA(VLOOKUP(A344,'202202KSRheinbergerMühlen'!$B$4:$F$575,5,FALSE)),"",VLOOKUP(A344,'202202KSRheinbergerMühlen'!$B$4:$F$575,5,FALSE))&"") -> St | F344: 6.3.6.
A345: 6.3.6. | E345: =IF(ISBLANK(A345),"",IF(ISNA(VLOOKUP(A345,'202202KSRheinbergerMühlen'!$B$4:$F$575,5,FALSE)),"",VLOOKUP(A345,'202202KSRheinbergerMühlen'!$B$4:$F$575,5,FALSE))&"") -> St

Sheet Config
A1: Configuration Version | B1: 2
A2: Service Specification Index | B2: 0
A3: Dangl.AVA.Converter www.dangl-it.com V2.28.9 ©2026
A4: Worksheetname Overview | B4: 202202KSRheinbergerMühlen
A5: Worksheetname ProjectInfo | B5: Projektinfo
A6: Worksheetname Calculation | B6: Kalkulation
A7: Dieses Arbeitsblatt enthält Konfigurationsdaten, die dem späteren Einlesen als GAEB Datei dienen. Bitte ändern Sie keine Werte.
A8: This worksheet contains configuration data needed so the file can be read again as GAEB file. Please do not modify any values.
A9: Created at 13.01.2026 18:47 (UTC) | B9: 46035.783
