Workbook

Sheet 049
A1: Projektname | B1: =IF(Projektinfo!B1="","",Projektinfo!B1) -> 049
A2: MwSt.
A3: Typ | B3: Ordnungszahl | C3: Kurztext | D3: Langtext | E3: Menge | F3: Einheit | G3: Einheitspreis | H3: Gesamtpreis | I3: Nachlass | J3: Preis nach Nachlass | K3: MwSt.
A4: Leistungsbeschreibung | C4: Trockenbau
A5: Hinweistext | C5: DECKBLATT | D5: Leistungsverzeichnis Anliegend übersenden wir Ihnen ein Leistungsverzeichnis mit der Bitte um ein Angebot ____________________________________________________________________ Bauvorhaben Umbau und Sanierung Jugendzentrum STEP Stepgesstraße 20 41061 Mönchengladbach Gewerk Trockenbau Auftraggeber Stadt Mönchengladbach, Der Oberbürgermeister GMMG Gebäudemanagement 41050 Mönchengladbach ____________________________________________________________________ Einzeltermine nach Bauzeitenplan 05.12.2025 | K5: ="" | M5: 958eedbb-a44d-4be5-896c-310f2905bf09
A6: Hinweistext | C6: Inhaltsverzeichnis | D6: Inhaltsverzeichnis A. 0 = Abkürzungsverzeichnis A. 1 = Baubeschreibung A. 2 = Vorbemerkungen zum Leistungsverzeichnis A. 3 = Allgemeine Technische Vorbemerkungen (ATV) A. 4 = Zusätzliche Technische Vertragsbedingungen (ZTV) A. 5 = Bauschild A. 6 = Allgemeine Hinweise zur Preisbildung A. 7 = Ausführungsunterlagen A. 8 = ZTV SiGeKo A. 9 = Materialökologie A. 10 = Zusätzliche allgemeine Technische Vorbemerkungen A. 11 = zusätzliche Technische Vorbemerkung A. 12 = Aufstellung beigelegter Anlagen A. 13 = ATV für Bauleistungen A. 14 = Hinweis Positionsbeschreibung Titel 00 = Technische Vorbemerkungen Titel 01 = Planung, Prüfung und Bemusterung Titel 02 = Baustelleneinrichtung Titel 03 = Kellergeschoss Titel 04 = Sockelgeschoss Titel 05 = Erdgeschoss Titel 06 = Obergeschoss Titel 07 = Dachgeschoss Titel 08 = Zusätzliche Ausführungen Titel 09 = Dokumentation Titel 10 = Stundenlohnarbeiten | K6: ="" | M6: c5d114a5-c90e-49de-af02-bba1d607bff8
A7: Hinweistext | C7: A.0 Abkürzungsverzeichnis | D7: A.0 Abkürzungsverzeichnis AG = Auftraggeber AN = Auftragnehmer ARC = Architekt ATV = Allgemeine Technische Vertragsbedingungen BE = Baustelleneinrichtung BG Bau = Berufsgenossenschaft der Bauwirtschaft DepV = Deponieverordnung DIN = Deutsche Industrienorm EfbV = Entsorgungsfachbetriebeverordn ung EG = Erdgeschoss ELT = Elektroinstallation HLS = Heizung-Lüftung-Sanitär LAGA = Länderarbeitsgemeinschaft Abfall LOG = Logistiker LV = Leistungsverzeichnis OÜ = Objektüberwachung des AG RTP = Rahmenterminplan SiGeKo = Sicherheits- und Gesundheitskoordinator TGA = Technische Gebäudeausstattung üNN = über Normal-Null (in m) UVV = Unfallverhütungsvorschriften VOB = Verdingungsordnung für Bauleistungen ZTV = Zusätzliche technische Vertragsbedingungen ZVB = Zusätzliche Vertragsbedingungen | K7: ="" | M7: 73580009-9348-4c39-88d6-fdbd27793e84
A8: Hinweistext | C8: A.1 Baubeschreibung | D8: A.1 Baubeschreibung Bauherr und Aufgabenstellung Das Gebäudemanagement der Stadtverwaltung Mönchengladbach - kurz gmmg - hat nach einem vorangegangenen VGV-Verfahren Planungsleistungen der Phasen 3 bis 9 auf der Grundlage der Vorplanung und der Machbarkeitsstudie beauftragt. Neben den baurechtlichen und technischen Anforderungen sind folgende Maßnahmen vorgesehen: Kellergeschoss Einrichtung des Jugend-Partizipations-Cafés im ehemaligen Lagerraum mit Küche, Theke, Lager, Bühne, W-LAN-Ecke, Garderobe und Schließfächern Abtrennung einer Werkstatt für den Hausmeister Sanierung und Erweiterung der WC-Anlagen inkl. Behinderten-WC neuer Entrée-Bereich mit Sauberlaufzone überdachter Treffpunkt mit Spiel und Sitzgelegenheiten Lagerfläche für Spielmobil Sockelgeschoss Neugestaltung des offenen Bereiches und Einbau von Prallschutzwandbelägen Hebelift für Rollstuhl und Umbau der Treppenpodest-Situation Sanierung der WCs (auch in der Hausmeisterwohnung) und Einbau eines Behinderten-WCs Sanierung der Kassettendecken Schachtwand für TGA Überdachung des Innenhofes (Spielbereich) Wiederherstellung der ursprünglich vorhandenen Treppenanlage (gespiegelt) Errichtung eines Außenaufzuges für die barrierefreie Erschließung des gesamten Gebäudes Montage einer Zaunanlage mit Zugangstüre Abbruch Betonquader und Gestaltung der Freiflächen mit Bodendecker und Hecken Erdgeschoss Erweiterung der Foyer-Fläche zum Aktionsraum, neue Eingangssituation mit Sauberlaufzone vorgelagerter Grünstreifen Einrichtung eines Kunst- und Aktionsraumes Hebelift für Rollstuhl und Umbau der Treppenpodest-Situation zur barrierefreien Erschließung der Bühnenfläche Errichtung des 2. Rettungsweges für UG und EG durch Erweiterung des Treppenraumes Sanierung (vollständiger Rückbau) der WCs und Einbau eines Behinderten-WCs mit Wickeltisch Ausbau und Vergrößerung der Küche (vollständiger Rückbau) Umstrukturierung des Cafés mit Theke unter Mitnutzung des Balkons Schachtwand für TGA Einbau einer neuen Türanlage zum Treppenhaus Sanierung der Kassettendecken Obergeschoss barrierefreie Erschließung der Etage über Aufzug Montage einer Boulder-Wand mit Prallschutz Sanierung von WCs und Umkleide, Einrichtung eines Behinderten-WCs Einbau einer neuen Türanlage zum Treppenhaus Schachtwand für TGA Reihenbestuhlung für Veranstaltungen Dachgeschoss Sanierung des WC-Bereiches Sanierung des Medienraumes einschl. Brandschutzverglasung zum Luftraum Einbau Aufenthaltsraum auf der Empore mit Balkon zum Luftraum Schachtwand für TGA Die Herrichtung eines neuen Aktions- und Kunstraumes sowie von Ausstellungsflächen im EG sollen zu einer einladenden Eingangssituation im Erdgeschoss führen und die Offenheit und Neuausrichtung der Einrichtung nach außen darstellen. Äußerlich werden Teile der Betonflächen und Klinkerfugen, Pflasterflächen und ein Balkon instandgesetzt. Ferner wird die Außentreppe ergänzt und ein Aufzug errichtet. Interim Für die Dauer der Umbau- und Sanierungsmaßnahmen wird die Einrichtung komplett freigezogen, das Leiter- und Schulungsbüro im EG soll als Lagermöglichkeit dienen. Haustechnische Maßnahmen dort wären vorzuziehen oder zuletzt auszuführen. Die Interimsräume befinden sich im Vitus-Center (ca. 613 m² im ebenerdigen EG). Die Flächen eignen sich aufgrund des bereits umfangreich ausgestatteten Zustandes gut für eine temporäre Nutzung. Raumteilungen sind nur im geringen Umfang erforderlich und sollen in Tischlerarbeit erfolgen. Eine Vorabstimmung mit der Bauaufsichtsbehörde hat bereits stattgefunden. Ein Antrag auf Nutzugsänderung ist rechtzeitig zu stellen. Inklusion Die Anforderungen an eine barrierefreie öffentliche Einrichtung sind im Bestand oft nur schwer normgerecht umzusetzen, da die baulichen Gegebenheiten aus der Entstehungszeit des Gebäudes allein schon den geometrischen Vorgaben nicht entsprechen können. Von Seiten der Inklusionsbeauftragten wurden folgende Anpassungen gefordert: Die Erschließung des Obergeschosses ist derzeit nicht barrierefrei möglich. Somit ist die Erstellung eines Aufzuges im Sockelgeschoss neben der ebenfalls wieder hergerichteten Außentreppe vorgesehen. Dieser bedient das Erd- und Obergeschoss. Das Keller- und Sockelgeschoss kann von Straßenniveau aus erreicht werden. Aufgrund der verschachtelten Geometrie und der Höhenversätze auch innerhalb der Geschosse sind bereits Rampen vorhanden, die eine Barrierefreiheit gewährleisten sollen. Die nachträglich installierte Rampe im Jugendcafé entspricht dabei nicht den maximalen Steigungsregeln und wird durch einen Hubaufzug ersetzt werden. Zur Überwindung der Höhenunterschiede an der Treppenanlage im Sockelgeschoss (offener Bereich) ist dies ebenfalls eine einwandfreie Lösung zur Herstellung der Barrierefreiheit. Der Zugang zur Bühne wird ebenfalls barrierefrei hergestellt. Die zur Deckenkonstruktion gehörenden Rampen aus der Errichtungszeit vor dem Eingang zum Sockelgeschoss und innerhalb des Erdgeschosses sind ebenfalls etwas zu steil. Eine bauliche Anpassung an heutige Normen ist wirtschaftlich nicht darstellbar. In jedem Geschoss ist nun die Einrichtung eines Behinderten-WCs vorgesehen, dabei kann im Obergeschoss die normgerechte Ausgestaltung der Bewegungsflächen und sonstigen Maßregeln aufgrund der erforderlichen Eingriffe in den Bestand (statische Belange) nicht hundertprozentig erfolgen. Die Umsetzung weiterer Maßnahmen zur Herstellung der Barrierefreiheit wie zum Beispiel die Installation taktiler Leitsysteme, Schaffung von Kontrasten, Ertüchtigungsmaßnahmen für leichtgängige Türen usw. müssen im Zuge der weiteren Planung konkretisiert werden. Dafür empfiehlt sich die Beauftragung eines entsprechenden Sachverständigen, der auch das erforderliche Barrierefrei-Konzept erstellen muss. Nach ausführlicher Planungs-Besprechung mit der Inklusionsbeauftragten werden generell die Möglichkeiten von Erleichterungen akzeptiert, um die Wirtschaftlichkeit der Maßnahmen nicht zu gefährden. Die Situation der Barrierefreiheit wird sich durch die geplanten Eingriffe deutlich verbessern. Architektur / Innenarchitektur Ausgangssituation (Bestand) Der 5-geschossige Gebäudekomplex wurde als Jugendzentrum bauaufsichtlich genehmigt und 1981 fertiggestellt. Durch die Hanglage wird der Klinkerbau auf unterschiedlichen Ebenen erschlossen. Das Kellergeschoss ist von der Stepgesstraße über den Parkplatz erreichbar, während das Erdgeschoss derzeit nur über den Fußweg im Hans- Jonas-Park erschlossen wird. Die ehemalige Treppenanlage an der Stepgesstraße wurde vor unbestimmter Zeit abgebrochen. Das Gebäude ist mit seiner verwinkelten Geometrie ein zeittypischer Kommunalbau, der vor allem durch seine innenräumliche Ausgestaltung überzeugt. Die Materialität und die Formensprache sind dabei Innen wie Außen konsequent identisch. Eingriffe / Urheberrechte Bezogen auf die Anforderungen, die derzeit an öffentliche Gebäude gestellt werden, besteht ein enormer Anpassungsbedarf. Mit den geplanten Eingriffen wird schonend und respektvoll mit der Substanz und dem Erhalt der Gesamterscheinung umgegangen. Notwendige Eingriffe werden als solche erkennbar sein und nicht dem Versuch unterliegen, das Gebäude unter heutigen Gesichtspunkten "fertig zu bauen". Einziger Schwerpunkt der Außengestaltung ist die geplante neue Erschließungstreppe inklusive des Aufzugsschachtes. Unter Einbeziehung der zu sanierenden Klinkerflächen an den Fluchtbalkonen soll ein der Umgebung farblich angepasster "Erschließungsknoten" entstehen, der den Besucher zukünftig mit seiner äußerst einladenden Geste in das Gebäude lenken soll, Orientierung bietet und charakteristisches Merkmal der Einrichtung werden kann. Atmosphären Die bisherige Nutzung des Gebäudes hat ihre Spuren hinterlassen. Es ist sehr schön zu erkennen, wie sich Nutzer und Besucher über die Jahre mit dem Bestand arrangierten und dabei fast liebevoll mit kreativem Reichtum und in Teilen vielleicht ungewollt einfallsreich improvisiert das Ihre zur Funktion beigetragen haben. Es ist erstrebenswert, die gewachsene Atmosphäre möglichst weitreichend zu erhalten und erforderliche Maßnahmen behutsam durchzuführen. Farben und Materialien Das Gebäude besteht aus den Farben des verwendeten Materials wie Klinker und Beton. Geplante Eingriffe sind in der Studie farbig dargestellt, um dem Anspruch einer klaren Abgrenzung von Alt und Neu gerecht zu werden. Dies bedeutet aber keineswegs eine Festlegung auf konkrete Töne und dient lediglich als Platzhalter. Innenausbau / Einrichtung Die Einrichtungsplanung (Qualitäten und Quantitäten) ist mit dem Nutzer abgestimmt und wurde in den wesentlichen Bereichen visualisiert. Holz- und Metallflächen sollen dominieren, das Jugendpartizipationscafé erhält einen industriellen Charakter mit robusten Materialien und Oberflächen. Brandschutz Der zweite Rettungsweg für das geplante Partizipationscafé im Kellergeschoss kann über die vorhandene Treppe ins Erdgeschoss geführt werden, wenn wie dargestellt der Treppenraum dort bis zur Fassade erweitert und mindestens feuerhemmend ausgebildet wird. Türen im Verlauf sind ebenfalls mindestens feuerhemmend sowie rauchdicht und selbstschließend nach DIN EN 13501-2 auszuführen. Der Medienraum im Obergeschoss kann mangels zweitem Rettungsweg nicht als Aufenthaltsraum genutzt werden. Die Verglasung zum Luftraum ist feuerhemmend nach DIN EN 13501-2 (E 30) zu verschließen. Für den geplanten Besprechungsraum auf der Empore ist ein zweiter Rettungsweg über das Fenster (mind. 0,90 x 1,20 m im Lichten) erforderlich und möglich. Da die Brüstungshöhe bezogen auf die darunterliegende Geländehöhe mehr als 8 m beträgt, muss mit dem Hubleiterwagen der Feuerwehr angeleitert werden. Es wird davon ausgegangen, dass entsprechende Aufstellflächen im öffentlichen Straßenbereich nachgewiesen werden können. Energieberatung / energetische Maßnahmen Künftig wird Wärme zu 75 % über Luft-Wasser-Wärmepumpen erzeugt, die restlichen 25 % über ein wasserstofffähiges Gasbrennwertgerät. Der nach Gebäudeenergiegesetz erforderliche Mindestanteil an erneuerbarer Energie (65 %) wird somit eingehalten. Eine Photovoltaik-Anlage mit rund 90 Modulen mit einer Leistung von etwa 40 kW peak wird auf dem bestehenden Dach installiert. Die Amortisation der Anlage wird mit rund achteinhalb Jahren angegeben. Die Autarkiequote soll bei rund 38 % liegen. Durch die Stromerzeugung wird eine CO²-Reduktion in Höhe von rund 12,4 Tonnen p.a. erwartet. Die gmmg hat eine CO²-Bilanzierung als Voraussetzung für eine IHEK-Förderung in Auftrag gegeben. Der Bericht der Energieberatung stellt die Energiebilanz im Ist-Zustand und nach geplanter Installation von Wärmepumpen und einer Photovoltaik-Anlage dar. Demnach können durch die geplanten Maßnahmen rechnerisch 31 % der Energie eingespart werden. Es ist geplant, möglichst zertifizierte Baustoffe zu verwenden, zum Beispiel Holz aus nachhaltiger Forstwirtschaft. Je nach Marktverfügbarkeit und Preislage werden auch recycelte Materialien wie zum Beispiel Fliesen verbaut. Zudem sollen recyclingfähige Materialien bevorzugt werden. Die Einrichtung soll in Teilen als Upcycling entstehen. So ist unter Beteiligung der Jugendlichen angedacht, ein Upcycling-Projekt für definierte Wandteilflächen auszuloben, für die unter Verwendung von nicht mehr benötigten Materialien eine gebrauchsfähige Funktionsfläche konstruiert werden soll. So kann zum Beispiel aus alten Holz- Weinkisten ein Wandregal entstehen, verzinkte Regalböden werden zur Pin- und Magnetwand und leere Flaschen erstrahlen als Leuchtkörper. Raumteiler aus Gabionen können als "Wechselausstellung" befüllt werden mit Sammlerstücken. Heizung Lüftung Sanitär MSR Heizung Die maroden Heizungsleitungen und Fußbodenheizungsverteiler werden saniert und die einzelnen Räume mit funkgesteuerten Raumthermostaten versehen. Durch den Einbau der Hebeliftanlagen und Aufstellen neuer Wände (evtl. in Klebetechnik) ist partiell ein Anpassen der Fußbodenheizung erforderlich. Im Erdgeschoss wird der gesamte Sanitär- und Küchenbereich entkernt und mitsamt Fußbodenheizung neu aufgebaut. Im Kellergeschoss frei unter der Decke verlegte Leitungen werden von der KMF-belasteten Wärmedämmung befreit und optisch ansprechend neu gedämmt. Lüftung / MSR Defekte und marode Lüftungsanlagen werden einschließlich der abgängigen Steuerung saniert und hocheffiziente Motoren eingebaut. Schadstoffhaltige Brandschutzklappen werden ausgetauscht. Die Anlagen zur Wärmerückgewinnung werden saniert und optimiert. Einzelne Anlagen in Verbindung mit der zukünftigen Nutzung des Jugendpartizipationscafés werden erneuert bzw. angepasst. Eine bedarfsgerechte Luftführung entsprechend der tatsächlichen Luftqualitäten wird hergestellt. Sanitär Aus hygienischen Gründen wird die gesamte Trinkwasserversorgung erneuert. Dabei wird auch die KMF-belastete Wärmedämmung ausgetauscht. Alle sanitären Einrichtungen werden erneuert. Erforderliche Installationen für die neu gestalteten Küchenbereiche werden nach Vorgabe des separaten Fachplaners ausgeführt. Die Ausstattung mit Geräten ist mit dem Nutzer abgestimmt. Ein rollstuhlgerechtes WC wird mit einem Wickeltisch ausgestattet. Elektrotechnik Aufbau einer PV-Anlage auf dem Dach mit einer Leistung von ca. 40 kW peak. Installation einer aufgeschalteten flächendeckenden Brandmeldeanlage gemäß Brandschutzkonzept. Herstellen einer Sicherheitsbeleuchtung und Kennzeichnung der Flucht- und Rettungswege gemäß Brandschutzkonzept. Erneuerung der gesamten Grund-Beleuchtung mittels LED-Lampen zum Teil als Lichtschienensystem für eine nutzerfreundliche da flexible Gestaltung der Ausleuchtungs-Szenerien. Zusätzlich atmosphärische Beleuchtung mittels Spots mit Direkt / Indirekt-Anteil und Pendelleuchten sowie LED-Stripes. Im Innenhof, im Treppenbereich und auf dem Balkon im Erd- und Obergeschoss sind Leuchten mit entsprechender Schutzart vorgesehen. Diese kommen auch im "offenen Umgang mit Kunst" zum Einsatz. Erneuerung der nicht mehr zulässigen Haupt- und Unterverteilungen sowie der Verkabelung mittels halogenfreier Leitungen. Aufbau einer strukturierten Verkabelung für ein flächendeckendes öffentliches WLAN-Netz im Gebäude. Aufbau der erforderlichen Installationen nach Angabe des Küchenplaners. Rückbau des kostenintensiven Notstromaggregates. Einbau einer Aufzugsanlage und Hebelifte für Rollstuhlfahrer zur Überwindung der "Split-Levels". Der vorhandene Lastenaufzug wird zurückgebaut. Für die erforderliche Veranstaltungstechnik im Jugendpartizipationscafé (KG) und im Veranstaltungssaal (EG) hat ein externer Fachplaner in Abstimmung mit dem Nutzer die Bedarfe geplant. Freianlagen Parallel zur Erstellung der Machbarkeitsstudie wurden die projektübergreifenden Planungen der Planergruppe Oberhausen hinsichtlich der Neugestaltung des Hans-Jonas-Parks fertig gestellt. Die formulierten Nutzungsanforderungen hinsichtlich der Ausgestaltung einer "Stadtoase" (Freiflächengestaltung und Spielgerät auf dem Grundstück des STEP) wurden dort planerisch wie auch kostenmäßig separat erfasst. Durch die vorliegende Planung ist der Freiraum neben der neuen Treppen- und Aufzugsanlage so gestaltet, dass keine unerwünschten und unkontrollierten Räume entstehen. Dies wird erreicht durch die Abtrennung des Bereiches zur Kontrolle des Zutritts und durch die unzugängliche Freiflächengestaltung mittels Bodendeckern und Hecken. Schadstoffe Eine orientierende Schadstoffuntersuchung hinsichtlich von Verdachtsfällen auf Asbest insbesondere im Subbereich von Putzen und Spachtelmassen, PCB, PAK und KMF hat mittels einer sachkundigen Begehung stattgefunden. Dabei wurden von verdächtigen Bausubstanzen Materialproben entnommen und im Labor auf den jeweiligen Schadstoffverdacht analysiert. Asbest - Bei der orientierenden Schadstoffuntersuchung wurde bei allen entnommenen Proben kein Asbest nachgewiesen. Asbestfundstellen sind die visuell eingestuften Dichtungsflansche und die Brandschutzklappen. Alle Arbeiten an asbesthaltigen Baustoffen müssen unter Berücksichtigung der Vorgaben aus der TRGS519 durchgeführt werden. Die Schutzmaßnahmen richten sich nach den durchzuführenden Arbeiten. Die Arbeiten an den asbesthaltigen Bauteilen dürfen nur durch fach- und sachkundige Firmen durchgeführt werden. Die personenbezogenen und die technischen Schutzmaßnahmen sind zwingend einzuhalten. KMF - Alle im Gebäude verbauten Mineralfasern werden als alte KMF eingestuft. Alle in Punkt 5 "Erkenntnisse zum Ortstermin" beschriebenen KMF-Fundstellen und alle nicht angesprochenen Fundstellen sind bei Eingriffen wie in Punkt 9 erläutert einzuordnen und zu behandeln. PCB - Bei der orientierenden Gebäudeuntersuchung wurden keine PCB-haltigen Materialien vorgefunden. PAK - Bei der orientierenden Gebäudeuntersuchung wurden keine PAK-haltigen Materialien vorgefunden. Caveat - Eventuell unerkannt vorliegende Altlasten Die mit dem Bericht beschriebenen Untersuchungen wurden sorgfältig und nach bestem Wissen und Gewissen durchgeführt. Naturgemäß können bei derartigen Begehungen aufgrund zum Teil mangelnder Demontage- und Zugangsmöglichkeit nicht immer alle schadstoffhaltigen Materialien erkannt werden. Treten bei ASI- Arbeiten bzw. bei Demontagen Zweifel an der Unbedenklichkeit bei zu demontierenden Teilen bzw. von Baustoffen auf, so sind die Arbeiten sofort einzustellen und die infrage stehenden Teile sachverständig nachträglich weiterführend zu begutachten. Im Gebäude sind zum Teil (SG und EG) Kassettendecken aus Stahlbeton vorhanden, deren quadratische Hohlräume ursprünglich vermutlich zur optischen Erhöhung der Räume dienten und teilweise Lampenauslässe enthalten. Teilweise sind nach Fertigstellung des Gebäudes Hohlräume mit eingelegten Heraklith-Platten und aufgelegter KMF eingebaut worden. Da sämtliche Elektroinstallationen erneuert werden müssen, Abhangdecken aber aufgrund der Reduktion der Raumhöhen ebenso wie eine auf-Putz-Installation nicht in Frage kommen, werden die Decken in den Ursprungszustand versetzt und mit abgehängten Lichtschienensystemen versehen. Ein Rückbau- und Entsorgungskonzept wird zur Ausführungsplanung durch einen Schadstoff-Sachverständigen erstellt. Arbeitsschutz Derzeit befindet sich im Kellergeschoss ein Wasch- und Putzraum sowie ein Aufenthaltsraum für das Reinigungspersonal (ca. 2 Personen). Ein Pausenraum ist gemäß den Arbeitsstättenrichtlinien erst ab 10 Beschäftigten erforderlich. Daher wurde in der Studie auf einen entsprechenden Nachweis verzichtet. Alle weiteren Mitarbeiter der Einrichtung werden in den Büros oder sonstigen Räumlichkeiten wie Café etc. pausieren. Zwecks Festlegung von erforderlichen Rettungswegbreiten und der Anwendbarkeit der Versammlungsstättenverordnung sowie zur Festlegung der Anzahl von erforderlichen Sanitäranlagen ist die geplante Anzahl von Personen in den jeweiligen Bereichen nach Absprache zwischen Bauherrin und Nutzer abgestimmt worden. Im weiteren Verlauf der Planung sind diese Annahmen laufend zu verifizieren. Die Möblierung und Ausstattung des STEP wird für die Baumaßnahme vollständig aus den zu bearbeitenden Räumen entfernt und eingelagert oder im Interim verwendet. Möglich ist die Einlagerung in Räumen der Einrichtung, die in der Vorplanung nicht farbig bzw. nicht grau hinterlegt sind. Unter Berücksichtigung eventueller Verkehrs- und Transportwege für die ausführenden Handwerker eignen sich dabei die an der Außenwand angeordneten Räume (v.a. KG 1.06 Übungsraum, SG 1.04 Werkraum, SG 1.03 Betreuung, SG 1.27-29 Spielgruppe und SG 1.31 Spielraum). Sollte in diesen Räumen aufgrund von Arbeiten an den Ver- und Entsorgungssträngen Maßnahmen erforderlich sein, können diese vor der Einlagerung zeitlich vorgezogen werden. Bezeichnung des Vorhabens: Umbau und Sanierung Jugendzentrum STEP, teilweise Errichtung und Nutzungsänderung Im Wesentlichen handelt es sich bei der eingereichten Genehmigungsplanung um folgende Maßnahmen: Untergeschoss Nutzungsänderung / Umbau: 01-KG-G0010 (derzeit ohne Nutzung) ist geplant als überdachter Treffpunkt mit Spiel und Sitzgelegenheiten 01-KG-00010 ist geplant als Jugendpartizipationscafé mit Küche (01-KG-00030), Theke, Lager (01-KG-00040), Bühne, Computerecke, Garderobe und Schließfächern (alle Räume derzeit Lagerraum) 01-KG-00050 (derzeit Lager) ist geplant als Hausmeister-Werkstatt 01-KG-00060 (derzeit Raum für Notstromaggregat) ist geplant als Raum für Elektrotechnik 01-KG-00080 (derzeit Instrumentenraum) ist geplant als Technikraum für die Lüftungsanlage und als Batteriespeicherraum für die neu geplante Photovoltaikanlage auf der Dachfläche Errichtung: 01-KG-F0010 (derzeit überdachter Außenraum) ist geplant als neuer Entrée-Bereich mit Sauberlaufzone 01-KG-00200, 01-KG-F0030, 01-KG-00160, 01-KG-00170, 01-KG-180, 01-KG-00190 sind geplant als Behinderten-WC, Flur, Waschräume und Toilettenräume (alle Räume derzeit überdachter Außenbereich) 01-KG-00230 (derzeit überdachter Außenbereich) ist geplant als Lager für das Spielmobil Sockelgeschoss Umbau: Neugestaltung des offenen Bereiches und Einbau von Prallschutzwandbelägen 01-SG-00060 Einbau eines Behinderten-WCs Installation Hebelift für Rollstuhl und Umbau der Treppenpodest-Situation 01-SG-00010 Einbau einer Schachtwand für TGA 01-SG-00150 (derzeit Abstellraum) ist geplant für Einbau der BMZ als neuer Standort (derzeit 01- EG-00010) Errichtung: Überdachung der Außenterrasse als Wetterschutz Wiederherstellung der ursprünglich vorhandenen Treppenanlage in das EG (gespiegelt) Errichtung eines Außenaufzuges für die barrierefreie Erschließung von SG bis OG Montage einer Zaunanlage mit Zugangstüre an der Treppenanlage Abbruch Betonquader und Gestaltung der Freiflächen mit Bodendecker und Hecken Sanierung: Sanierung der Sanitärräume (auch in der Hausmeisterwohnung) Sanierung der Kassettendecken nach Rückbau- und Entsorgungskonzept Erdgeschoss Umbau / Sanierung: 01-EG-00010 Vergrößerung der Aktions- und Kunstraumes Installation Hebelift für Rollstuhl und Umbau der Treppenpodeste zur barrierefreien Erschließung der Bühnenfläche Errichtung des 2. Rettungsweges für UG und EG durch Erweiterung des Treppenraumes Sanierung (vollständiger Rückbau) der WCs und Einbau eines Behinderten-WCs mit Wickeltisch Ausbau und Vergrößerung der Küche (vollständiger Rückbau) Umstrukturierung des Cafés mit Theke unter Mitnutzung des Balkons Einbau von Schachtwänden für die TGA Sanierung der Kassettendecken nach Rückbau- und Entsorgungskonzept 01-EG-TF010 Einbau einer neuen Türanlage zum Treppenhaus Errichtung: 01-EG-F0010 (derzeit überdachter Außenraum) ist geplant als Ausstellungs- und Foyer-Fläche Obergeschoss Umbau / Sanierung: 01-1O-00030 barrierefreie Erschließung der Etage über Aufzug 01-1O-00030 Montage einer Boulder-Wand mit Prallschutz Sanierung von WCs und Umkleide, Einrichtung eines Behinderten-WCs 01-1O-TF010 Einbau einer neuen Türanlage zum Treppenhaus Einbau von Schachtwand für TGA 01-1O-00030 Reihenbestuhlung für Veranstaltungen gemäß Bestuhlungspläne Dachgeschoss Nutzungsänderung / Errichtung: 01-EM-00040 (derzeit Balkon) ist geplant als abgetrennter Besprechungsraum mit Balkon Umbau / Sanierung: Sanierung des WC-Bereiches 01-EM-00010 Sanierung des Medienraumes einschl. Brandschutzverglasung zum Luftraum Einbau von Schachtwand für TGA Darüber hinaus sind im Wesentlichen die folgenden Maßnahmen geplant: Errichtung einer Photovoltaik-Anlage auf dem Dach der Einrichtung Aufstellung von Wärmepumpen im Außenbereich Erneuerung des Gasbrennwert-Heizkessels Erneuerung / Sanierung der elektrischen Anlagen über alle Geschosse Erneuerung der BMA und BMZ Erneuerung / Sanierung der Trinkwasserleitungen und Sanitärobjekte in allen Etagen Brandschutztechnische Sanierung gemäß Brandschutzkonzept über alle Geschosse Erneuerung bzw. Instandsetzung der RLT-Anlagen Stilllegung des Getränkeaufzuges von SG bis EG Leistungsumfang dieser Ausschreibung: Die GBA Gesellschaft für Bioanalytik mbH aus Mönchengladbach und die Z² Umwelttechnik GmbH aus Viersen haben Gebäudesubstanzuntersuchungen durchgeführt. Die folgenden Unterlagen liegen dieser Leistungsbeschreibung bei und sind gleichermaßen Vertragsbestandteil: Ausführungsplanung: Umbau und Sanierung STEP Mönchengladbach, M. = 1 : 50, Baumschlager Eberle Pagelhenn GmbH, Stand 14.11.2024. Gebäudeuntersuchung auf Schadstoffe, Objekt: Jugendzentrum Step, Stepgesstr. 20, Mönchengladbach, Bericht Nr. 20900282A. GBA Gesellschaft für Bioanalytik mbH, 23.03.2020. Schadstoffkataster, Stellungnahme zu den durchgeführten Gebäudesubstanzuntersuchungen. BVH: Mönchengladbach, Stepgesstraße - Jugendzentrum STEP. Projektnummer 2024-144.0, Z² Umwelttechnik GmbH, 28.02.2025. Wesentliche Aspekte der vorgesehenen Sanierungsmaßnahmen sind: Demontage einer asbesthaltigen Brandschutzklappe Demontage einer asbesthaltigen Abdichtung unterhalb des Estrichs im Bereich des Kellergeschosses Demontage von Asbestzementplatten an der Unterseite der Sitzbänke in der Kaminecke im Bereich des Erdgeschosses Demontage der KMF-Dämmung oberhalb der Heraklith-Deckenelemente, welche im gesamten Gebäude weit verbreitet sind. Diese sowie weitere, kleinere Demontage- und Teilabbruch-Maßnahmen sind unten sowie in den Planungsunterlagen der Baumschlager Eberle Pagelhenn GmbH detailliert aufgeführt. Alle Abfälle aus der Schadstoffsanierung und den Demontage- bzw. Teilrückbauarbeiten sind einer externen Verwertung / Beseitigung zuzuführen. Die Bereitstellung zur Entsorgung, Transportkosten, Kippgebühren und sonstige Neben- & Verwaltungskosten der Entsorgung sind in die u.g. Positionen einzupreisen. | K8: ="" | M8: 178c4929-6d08-41ba-b931-135f3f96162b
A9: Hinweistext | C9: A.2 Vorbemerkungen zum Leistungsverzeichniss | D9: A.2 Vorbemerkungen zum Leistungsverzeichniss Zusätzliche technische Vertragsbedingungen zur VOB, Teil C zu § 7 Abs. (1) - (3) VOB/A und Anhang TS gemäß Abs. 1 des Abschnitts 0 der ATV DIN 18299: Die folgenden Regelungen sind bei allen Titeln des Leistungsverzeichnisses zu beachten. Im Weiteren wird explizit auf die Ausführungen in der Leistungsbeschreibung hingewiesen. Soweit in der Leistungsbeschreibung auf technische Spezifikationen (z. B. nationale Normen, mit denen europäische Normen umgesetzt werden, europäische technische Zulassungen, gemeinsame technische Spezifikationen, internationale Normen) Bezug genommen wird, werden auch ohne den ausdrücklichen Zusatz: "oder gleichwertig", immer gleichwertige Technische Spezifikationen in Bezug genommen. | K9: ="" | M9: 3c728cc0-6051-42f1-a00d-81f43397fe14
A10: Hinweistext | C10: A.3 Allgemeine Technische Vorbemerkungen | D10: A.3 ATV Die laufende Nummerierung der nachfolgenden Punkte bezieht sich auf die Vorgaben der VOB/Teil C,DIN 18299. Nachstehend sind die Angaben für alle Gewerke aufgeführt Für die ausgeschriebenen Leistungen gelten die jeweils relevanten Aussagen A3.1Angaben zur Baustelle A3.1.1Lage der Baustelle, Umgebungsbedingungen, Zufahrtsmöglichkeiten und Beschaffenheit der Zufahrt sowie etwaige Einschränkungen bei ihrer Benutzung. wie Baustelleneinrichtungsplan (des AN) A3.1.2Besondere Belastungen aus Immissionen sowie besondere klimatische oder betrieblicheBedingungen. Keine A3.1.3Art und Lage der baulichen Anlagen, z. B. auch Anzahl und Höhe der Geschosse. siehe Baubeschreibung A3.1.4Verkehrsverhältnisse auf der Baustelle, insbesondere Verkehrsbeschränkungen. keine wesentlichen Einschränkungen A3.1.5Für den Verkehr freizuhaltende Flächen. PKW-Stellplätze können genutzt werden A3.1.6Art, Lage , Maße und Nutzbarkeit von Transporteinrichtungen und Transportwegen, z. B. Montageöffnungen. wie Baustelleneinrichtungsplan (des AN) A3.1.7Lage, Art, Anschlusswert und Bedingungen für das Überlassen von Anschlüssen für Wasser, Energie und Abwasser. wie Baustelleneinrichtungsplan (des AN) A3.1.8Lage und Ausmaß der dem Auftragnehmer für die Ausführung seiner Leistungen zur Benutzung oder Mitbenutzung überlassenen Flächen, Räume. wie Baustelleneinrichtungsplan (des AN) Im Bereich der Baustelle stehen Flächen zur Verfügung Die Zuweisung der Fläche erfolgt durch die AG-Bauleitung A3.1.9Bodenverhältnisse, Baugrund und seine Tragfähigkeit. Ergebnisse von Bodenuntersuchungen. nicht Bestandteil dieser Ausschreibung A3.1.10Hydrologische Werte von Grundwasser und Gewässern. Art, Lage, Abfluss, Abflussvermögen und Hochwasserverhältnisse von Vorflutern. Ergebnisse von Wasseranalysen. nicht Bestandteil dieser Ausschreibung A3.1.11Besondere umweltrechtliche Vorschriften. allgemeine und gesetzliche Anforderungen wie z.B. Lärmschutz sind einzuhalten A3.1.12Besondere Vorgaben für die Entsorgung, z. B. besondere Beschränkungen für die Beseitigung von Abwasser und Abfall. allgemeine und gesetzliche Anforderungen sind einzuhalten A3.1.13Schutzgebiete oder Schutzzeiten im Bereich der Baustelle, z. B. wegen Forderungen des Gewässer-, Boden-, Natur-, Landschafts- oder Immissionsschutzes; vorliegende Fachgutachten oder dergleichen. allgemeine und gesetzliche Anforderungen sind einzuhalten A3.1.14Art und Umfang des Schutzes von Bäumen, Pflanzenbeständen, Vegetationsflächen, Verkehrsflächen, Bauteilen, Bauwerken, Grenzsteinen und dergleichen im Bereich der Baustelle. Vegetationsflächen werden bauseits für den Baustellenbetrieb freigehalten (Vorbereitet) andere Vegetations-Bereiche sind nach BE-Plan des AN zu schützen A3.1.15Im Bereich der Baustelle vorhandene Anlagen, insbesondere Abwasser- und Versorgungsleitungen. Siehe Lageplan zum Bestand im Rahmen der Baustelleneinrichtungsplanung des AN A3.1.16Bekannte oder vermutete Hindernisse im Bereich der Baustelle, z. B. Leitungen, Kabel, Dräne, Kanäle, Bauwerksreste und, soweit bekannt, deren Eigentümer. siehe Ausführungsplanung Bestand TGA A3.1.17Bestätigung, dass die im jeweiligen Bundesland geltenden Anforderungen zu Erkundungs- und gegebenenfalls Räumungsmaßnahmen hinsichtlich Kampfmitteln erfüllt wurden. nicht Bestandteil dieser Ausschreibung A3.1.18Ggf. gemäß der Baustellenverordnung getroffene Maßnahmen. keine A3.1.19Besondere Anordnungen, Vorschriften und Maßnahmen der Eigentümer (oder der anderen Weisungsberechtigten) von Leitungen, Kabeln, Dränen, Kanälen, Straßen, Wegen, Gewässern, Gleisen, Zäunen und dergleichen im Bereich der Baustelle. keine A3.1.20Art und Umfang von Schadstoffbelastungen, z. B. des Bodens, der Gewässer, der Luft, der Stoffe und Bauteile; vorliegende Fachgutachten oder dergleichen. nicht Bestandteil dieser Ausschreibung A3.1.21 Art und Zeit der vom Auftraggeber veranlassten Vorarbeiten. keine A3.1.22 Arbeiten anderer Unternehmer auf der Baustelle. Gewerk TGA (ELT, Klima und Lüftung) Gewerk Rohbau A3.2 Angaben zur Ausführung A3.2.1 Vorgesehene Arbeitsabschnitte, Arbeitsunterbrechungen und Arbeitsbeschränkungen nach Art, Ort und Zeit sowie Abhängigkeit von Leistungen anderer. siehe Leistungsbeschreibung A3.2.2Besondere Erschwernisse während der Ausführung, z.B. Arbeiten in Räumen, in denen derBetrieb weiterläuft, Arbeiten im Bereich von Verkehrswegen, oder bei außergewöhnlichenäußeren Einflüssen. s. Leistungsbeschreibungen A3.2.3Besondere Anforderungen für Arbeiten für Arbeiten in kontaminierten Bereichen, ggf.besondere Anordnungen für Schutz- und Sicherheitsmaßnahmen. s. Leistungsbeschreibungen A3.2.4Besondere Anforderungen an die Baustelleneinrichtung und Entsorgungseinrichtungen,z.B. Behälter für die getrennte Erfassung. s. Leistungsbeschreibungen A3.2.5Besonderheiten der Regelung und Sicherung des Verkehrs, ggf. auch, wieweit der Auftraggeber die Durchführung der erforderlichen Maßnahmen übernimmt. im Rahmen der Baustelleneinrichtung A3.2.6Besondere Anforderungen an das Auf- und Abbauen sowie Vorhalten von Gerüsten. s. Leistungsbeschreibungen A3.2.7Mitbenutzung fremder Gerüste, Hebezeuge, Aufzüge, Aufenthalts- und Lagerräume, Einrichtungen und dergleichen durch den Auftragnehmer. s. Leistungsbeschreibungen A3.2.8Wie lange, für welche Arbeiten und ggf. für welche Beanspruchung der Auftragnehmer Gerüste, Hebezeuge, Aufzüge, Aufenthalts- und Lagerräume, Einrichtungen und dgl. für andere Unternehmer vorzuhalten hat. s. Leistungsbeschreibungen A3.2.9Verwendung oder Mitverwendung von wiederaufbereiteten (Recycling-) Stoffen. Siehe Leistungspositionen A3.2.10Anforderungen an wiederaufbereitete (Recycling-)Stoffe und an nicht genormte Stoffe und Bauteile. Siehe Leistungspositionen A3.2.11Besondere Anforderungen an Art, Güte und Umweltverträglichkeit der Stoffe und Bauteile, auch z. B. an die schnelle biologische Abbaubarkeit von Hilfsstoffen. Siehe Leistungspositionen A3.2.12Art und Umfang der vom Auftraggeber verlangten Eignungs- und Gütenachweise. Siehe Leistungspositionen A3.2.13Unter welchen Bedingungen auf der Baustelle gewonnene Baustoffe verwendet werden dürfen oder müssen oder einer anderen Verwertung zuzuführen sind. nicht Bestandteil dieser Ausschreibung A3.2.14Art, Zusammensetzung und Menge der aus dem Bereich des Auftraggebers zu entsorgenden Böden, Stoffe und Bauteile; Art der Verwertung bzw. bei Abfall die Entsorgungsanlage; Anforderungen an die Nachweise über Transporte, Entsorgung und die vom Auftraggeber zu tragenden Entsorgungskosten. nicht Bestandteil dieser Ausschreibung A3.2.15Art, Anzahl, Menge oder Masse der Stoffe und Bauteile, die vom Auftraggeber beigestellt werden sowie Art, genaue Bezeichnung des Ortes und Zeit ihrer Übergabe. nicht Bestandteil dieser Ausschreibung A3.2.16In welchen Umfang der Auftraggeber Abladen, Lagern und Transport von Stoffen und Bauteilen übernimmt oder dafür dem Auftragnehmer Geräte oder Arbeitskräfte zur Verfügung stellt. Auftrag und Aufgabe des AN der AG übernimmt keine Transporte A3.2.17Leistungen für andere Unternehmer. Siehe Leistungspositionen A3.2.18Mitwirken beim Einstellen von Anlageteilen und bei der Inbetriebnahme von Anlagen im Zusammenwirken mit anderen Beteiligten, z.B. mit dem Auftragnehmer für die Gebäudeautomation. Siehe Leistungspositionen A3.2.19Benutzung von Teilen der Leistung vor der Abnahme. Siehe Leistungspositionen A3.2.20Übertragung der Wartung während der Dauer der Verjährungsfrist für die Mängelbeseitgungsansprüche für maschinelle und elektrotechnische / elektronische Anlagen oder Teile davon, bei denen die Wartung Einfluss auf die Sicherheit und die Funktionsfähigkeit hat (vergleiche § 13 Nr. 4 Abs. 2 VOB/B), durch einen besonderen Wartungsvertrag. Siehe Leistungspositionen A3.2.21Abrechnung nach bestimmten Zeichnungen oder Tabellen. gemäß VOB Teil C DIN 18299 Kapitel 5 | K10: ="" | M10: 749b552c-951e-434e-80fe-876f6b3741c7
